Workbook

Sheet Data for figure
A1: Figure 1 | B1: unit | C1: kt | D1: 1000 | G1: kt | J1: M CTU | N1: CTU
J2: 1000000
A3: ='factor influence'!W119 -> Final | B3: ='factor influence'!X119 -> 0 | C3: ='factor influence'!Y119 -> 0 | D3: ='factor influence'!Z119 -> 0 | E3: ='factor influence'!AA119 -> 0 | F3: ='factor influence'!AB119 -> 0 | G3: ='factor influence'!AC119 -> 0 | H3: ='factor influence'!AD119 -> 0 | ... T3: ='factor influence'!AP119 -> 0
A4: ='factor influence'!W120 -> Everything Max | B4: ='factor influence'!X120 -> 0 | C4: ='factor influence'!Y120 -> 0 | D4: ='factor influence'!Z120 -> 0 | E4: ='factor influence'!AA120 -> 0 | F4: ='factor influence'!AB120 -> 0 | G4: ='factor influence'!AC120 -> 0 | H4: ='factor influence'!AD120 -> 0 | ... T4: ='factor influence'!AP120 -> 0
A5: ='factor influence'!W121 -> 0 | B5: ='factor influence'!X121 -> Use amount | C5: ='factor influence'!Y121 -> 0 | D5: ='factor influence'!Z121 -> 0 | E5: ='factor influence'!AA121 -> 0 | F5: ='factor influence'!AB121 -> Emission to wastewater | G5: ='factor influence'!AC121 -> 0 | H5: ='factor influence'!AD121 -> 0 | ... T5: ='factor influence'!AP121 -> 0
A6: ='factor influence'!W122 -> 0 | B6: ='factor influence'!X122 -> Electronic | C6: ='factor influence'!Y122 -> Semiconductor | D6: ='factor influence'!Z122 -> Total | E6: ='factor influence'!AA122 -> 0 | F6: ='factor influence'!AB122 -> Electronic | G6: ='factor influence'!AC122 -> Semiconductor | H6: ='factor influence'!AD122 -> Total | ... T6: ='factor influence'!AP122 -> Semiconductor
A7: ='factor influence'!W123 -> 2020 | B7: =('factor influence'!X123)/1000 -> 29.461576 | C7: =('factor influence'!Y123)/1000 -> 0.037635686 | D7: =('factor influence'!Z123)/1000 -> 29.499212 | E7: =('factor influence'!AA123)/1000 -> 0 | F7: =('factor influence'!AB123)/1000 -> 3.8849031 | G7: =('factor influence'!AC123)/1000 -> 0.020549768 | H7: =('factor influence'!AD123)/1000 -> 3.9054528 | I7: ='factor influence'!AE123 -> 0 | J7: ='factor influence'!AF123 -> 38904529 | K7: ='factor influence'!AG123 -> 205791.24 | L7: ='factor influence'!AH123 -> 39110321 | M7: ='factor influence'!AI123 -> 0 | N7: ='factor influence'!AJ123 -> 29347668 | O7: ='factor influence'!AK123 -> 155238.82 | P7: ='factor influence'!AL123 -> 29502907 | ... T7: ='factor influence'!AP123 -> 1.0928425
A8: ='factor influence'!W124 -> 2021 | B8: =('factor influence'!X124)/1000 -> 31.059794 | C8: =('factor influence'!Y124)/1000 -> 0.041129877 | D8: =('factor influence'!Z124)/1000 -> 31.100924 | E8: =('factor influence'!AA124)/1000 -> 0 | F8: =('factor influence'!AB124)/1000 -> 4.0956495 | G8: =('factor influence'!AC124)/1000 -> 0.022457659 | H8: =('factor influence'!AD124)/1000 -> 4.1181071 | I8: ='factor influence'!AE124 -> 0 | J8: ='factor influence'!AF124 -> 41015004 | K8: ='factor influence'!AG124 -> 224897.41 | L8: ='factor influence'!AH124 -> 41239902 | M8: ='factor influence'!AI124 -> 0 | N8: ='factor influence'!AJ124 -> 30939706 | O8: ='factor influence'!AK124 -> 169651.57 | P8: ='factor influence'!AL124 -> 31109358 | ... T8: ='factor influence'!AP124 -> 1.0928425
A9: ='factor influence'!W125 -> 2022 | B9: =('factor influence'!X125)/1000 -> 32.744711 | C9: =('factor influence'!Y125)/1000 -> 0.044948476 | D9: =('factor influence'!Z125)/1000 -> 32.78966 | E9: =('factor influence'!AA125)/1000 -> 0 | F9: =('factor influence'!AB125)/1000 -> 4.3178284 | G9: =('factor influence'!AC125)/1000 -> 0.024542683 | H9: =('factor influence'!AD125)/1000 -> 4.3423711 | I9: ='factor influence'!AE125 -> 0 | J9: ='factor influence'!AF125 -> 43239967 | K9: ='factor influence'!AG125 -> 245777.44 | L9: ='factor influence'!AH125 -> 43485744 | M9: ='factor influence'!AI125 -> 0 | N9: ='factor influence'!AJ125 -> 32618109 | O9: ='factor influence'!AK125 -> 185402.44 | P9: ='factor influence'!AL125 -> 32803512 | ... T9: ='factor influence'!AP125 -> 1.0928425
A10: ='factor influence'!W126 -> 2023 | B10: =('factor influence'!X126)/1000 -> 34.521031 | C10: =('factor influence'!Y126)/1000 -> 0.049121603 | D10: =('factor influence'!Z126)/1000 -> 34.570153 | E10: =('factor influence'!AA126)/1000 -> 0 | F10: =('factor influence'!AB126)/1000 -> 4.5520599 | G10: =('factor influence'!AC126)/1000 -> 0.026821287 | H10: =('factor influence'!AD126)/1000 -> 4.5788812 | I10: ='factor influence'!AE126 -> 0 | J10: ='factor influence'!AF126 -> 45585628 | K10: ='factor influence'!AG126 -> 268596.03 | L10: ='factor influence'!AH126 -> 45854224 | M10: ='factor influence'!AI126 -> 0 | N10: ='factor influence'!AJ126 -> 34387561 | O10: ='factor influence'!AK126 -> 202615.66 | P10: ='factor influence'!AL126 -> 34590177 | ... T10: ='factor influence'!AP126 -> 1.0928425
A11: ='factor influence'!W127 -> 2024 | B11: =('factor influence'!X127)/1000 -> 36.393712 | C11: =('factor influence'!Y127)/1000 -> 0.053682175 | D11: =('factor influence'!Z127)/1000 -> 36.447394 | E11: =('factor influence'!AA127)/1000 -> 0 | F11: =('factor influence'!AB127)/1000 -> 4.7989979 | G11: =('factor influence'!AC127)/1000 -> 0.029311441 | H11: =('factor influence'!AD127)/1000 -> 4.8283094 | I11: ='factor influence'!AE127 -> 0 | J11: ='factor influence'!AF127 -> 48058536 | K11: ='factor influence'!AG127 -> 293533.15 | L11: ='factor influence'!AH127 -> 48352069 | M11: ='factor influence'!AI127 -> 0 | N11: ='factor influence'!AJ127 -> 36253001 | O11: ='factor influence'!AK127 -> 221427 | P11: ='factor influence'!AL127 -> 36474428 | ... T11: ='factor influence'!AP127 -> 1.0928425
A12: ='factor influence'!W128 -> 2025 | B12: =('factor influence'!X128)/1000 -> 38.367981 | C12: =('factor influence'!Y128)/1000 -> 0.05866616 | D12: =('factor influence'!Z128)/1000 -> 38.426647 | E12: =('factor influence'!AA128)/1000 -> 0 | F12: =('factor influence'!AB128)/1000 -> 5.0593317 | G12: =('factor influence'!AC128)/1000 -> 0.032032788 | H12: =('factor influence'!AD128)/1000 -> 5.0913645 | I12: ='factor influence'!AE128 -> 0 | J12: ='factor influence'!AF128 -> 50665593 | K12: ='factor influence'!AG128 -> 320785.49 | L12: ='factor influence'!AH128 -> 50986379 | M12: ='factor influence'!AI128 -> 0 | N12: ='factor influence'!AJ128 -> 38219637 | O12: ='factor influence'!AK128 -> 241984.83 | P12: ='factor influence'!AL128 -> 38461622 | ... T12: ='factor influence'!AP128 -> 1.149
A13: ='factor influence'!W129 -> 2026 | B13: =('factor influence'!X129)/1000 -> 41.379867 | C13: =('factor influence'!Y129)/1000 -> 0.067407418 | D13: =('factor influence'!Z129)/1000 -> 41.447275 | E13: =('factor influence'!AA129)/1000 -> 0 | F13: =('factor influence'!AB129)/1000 -> 5.4564893 | G13: =('factor influence'!AC129)/1000 -> 0.036805673 | H13: =('factor influence'!AD129)/1000 -> 5.4932949 | I13: ='factor influence'!AE129 -> 0 | J13: ='factor influence'!AF129 -> 54642842 | K13: ='factor influence'!AG129 -> 368582.53 | L13: ='factor influence'!AH129 -> 55011425 | M13: ='factor influence'!AI129 -> 0 | N13: ='factor influence'!AJ129 -> 41219879 | O13: ='factor influence'!AK129 -> 278040.57 | P13: ='factor influence'!AL129 -> 41497919 | ... T13: ='factor influence'!AP129 -> 1.149
A14: ='factor influence'!W130 -> 2027 | B14: =('factor influence'!X130)/1000 -> 44.628187 | C14: =('factor influence'!Y130)/1000 -> 0.077451123 | D14: =('factor influence'!Z130)/1000 -> 44.705638 | E14: =('factor influence'!AA130)/1000 -> 0 | F14: =('factor influence'!AB130)/1000 -> 5.8848237 | G14: =('factor influence'!AC130)/1000 -> 0.042289719 | H14: =('factor influence'!AD130)/1000 -> 5.9271134 | I14: ='factor influence'!AE130 -> 0 | J14: ='factor influence'!AF130 -> 58932306 | K14: ='factor influence'!AG130 -> 423501.33 | L14: ='factor influence'!AH130 -> 59355807 | M14: ='factor influence'!AI130 -> 0 | N14: ='factor influence'!AJ130 -> 44455639 | O14: ='factor influence'!AK130 -> 319468.62 | P14: ='factor influence'!AL130 -> 44775108 | ... T14: ='factor influence'!AP130 -> 1.149
A15: ='factor influence'!W131 -> 2028 | B15: =('factor influence'!X131)/1000 -> 48.1315 | C15: =('factor influence'!Y131)/1000 -> 0.088991341 | D15: =('factor influence'!Z131)/1000 -> 48.220491 | E15: =('factor influence'!AA131)/1000 -> 0 | F15: =('factor influence'!AB131)/1000 -> 6.3467823 | G15: =('factor influence'!AC131)/1000 -> 0.048590887 | H15: =('factor influence'!AD131)/1000 -> 6.3953732 | I15: ='factor influence'!AE131 -> 0 | J15: ='factor influence'!AF131 -> 63558492 | K15: ='factor influence'!AG131 -> 486603.02 | L15: ='factor influence'!AH131 -> 64045095 | M15: ='factor influence'!AI131 -> 0 | N15: ='factor influence'!AJ131 -> 47945407 | O15: ='factor influence'!AK131 -> 367069.44 | P15: ='factor influence'!AL131 -> 48312476 | ... T15: ='factor influence'!AP131 -> 1.149
A16: ='factor influence'!W132 -> 2029 | B16: =('factor influence'!X132)/1000 -> 51.909822 | C16: =('factor influence'!Y132)/1000 -> 0.10225105 | D16: =('factor influence'!Z132)/1000 -> 52.012073 | E16: =('factor influence'!AA132)/1000 -> 0 | F16: =('factor influence'!AB132)/1000 -> 6.8450047 | G16: =('factor influence'!AC132)/1000 -> 0.055830929 | H16: =('factor influence'!AD132)/1000 -> 6.9008357 | I16: ='factor influence'!AE132 -> 0 | J16: ='factor influence'!AF132 -> 68547833 | K16: ='factor influence'!AG132 -> 559106.87 | L16: ='factor influence'!AH132 -> 69106940 | M16: ='factor influence'!AI132 -> 0 | N16: ='factor influence'!AJ132 -> 51709121 | O16: ='factor influence'!AK132 -> 421762.79 | P16: ='factor influence'!AL132 -> 52130884 | ... T16: ='factor influence'!AP132 -> 1.149
A17: ='factor influence'!W133 -> 2030 | B17: =('factor influence'!X133)/1000 -> 55.984743 | C17: =('factor influence'!Y133)/1000 -> 0.11748646 | D17: =('factor influence'!Z133)/1000 -> 56.10223 | E17: =('factor influence'!AA133)/1000 -> 0 | F17: =('factor influence'!AB133)/1000 -> 7.3823376 | G17: =('factor influence'!AC133)/1000 -> 0.064149737 | H17: =('factor influence'!AD133)/1000 -> 7.4464873 | I17: ='factor influence'!AE133 -> 0 | J17: ='factor influence'!AF133 -> 73928838 | K17: ='factor influence'!AG133 -> 642413.8 | L17: ='factor influence'!AH133 -> 74571252 | M17: ='factor influence'!AI133 -> 0 | N17: ='factor influence'!AJ133 -> 55768288 | O17: ='factor influence'!AK133 -> 484605.44 | P17: ='factor influence'!AL133 -> 56252893 | ... T17: ='factor influence'!AP133 -> 1.149
A18: ='factor influence'!W134 -> 2031 | B18: =('factor influence'!X134)/1000 -> 60.379546 | C18: =('factor influence'!Y134)/1000 -> 0.13499194 | D18: =('factor influence'!Z134)/1000 -> 60.514538 | E18: =('factor influence'!AA134)/1000 -> 0 | F18: =('factor influence'!AB134)/1000 -> 7.9618511 | G18: =('factor influence'!AC134)/1000 -> 0.073708048 | H18: =('factor influence'!AD134)/1000 -> 8.0355592 | I18: ='factor influence'!AE134 -> 0 | J18: ='factor influence'!AF134 -> 79732252 | K18: ='factor influence'!AG134 -> 738133.45 | L18: ='factor influence'!AH134 -> 80470385 | M18: ='factor influence'!AI134 -> 0 | N18: ='factor influence'!AJ134 -> 60146098 | O18: ='factor influence'!AK134 -> 556811.66 | P18: ='factor influence'!AL134 -> 60702910 | ... T18: ='factor influence'!AP134 -> 1.149
... A24: ='factor influence'!W140 -> Final | B24: =('factor influence'!X140)/1000 -> 0 | C24: =('factor influence'!Y140)/1000 -> 0 | D24: =('factor influence'!Z140)/1000 -> 0 | E24: =('factor influence'!AA140)/1000 -> 0 | F24: =('factor influence'!AB140)/1000 -> 0 | G24: =('factor influence'!AC140)/1000 -> 0 | H24: =('factor influence'!AD140)/1000 -> 0 | I24: ='factor influence'!AE140 -> 0 | J24: ='factor influence'!AF140 -> 0 | K24: ='factor influence'!AG140 -> 0 | L24: ='factor influence'!AH140 -> 0 | M24: ='factor influence'!AI140 -> 0 | N24: ='factor influence'!AJ140 -> 0 | O24: ='factor influence'!AK140 -> 0 | P24: ='factor influence'!AL140 -> 0 | ... T24: ='factor influence'!AP140 -> 0
A25: ='factor influence'!W141 -> Everything Min | B25: =('factor influence'!X141)/1000 -> 0 | C25: =('factor influence'!Y141)/1000 -> 0 | D25: =('factor influence'!Z141)/1000 -> 0 | E25: =('factor influence'!AA141)/1000 -> 0 | F25: =('factor influence'!AB141)/1000 -> 0 | G25: =('factor influence'!AC141)/1000 -> 0 | H25: =('factor influence'!AD141)/1000 -> 0 | I25: ='factor influence'!AE141 -> 0 | J25: ='factor influence'!AF141 -> 0 | K25: ='factor influence'!AG141 -> 0 | L25: ='factor influence'!AH141 -> 0 | M25: ='factor influence'!AI141 -> 0 | N25: ='factor influence'!AJ141 -> 0 | O25: ='factor influence'!AK141 -> 0 | P25: ='factor influence'!AL141 -> 0 | ... T25: ='factor influence'!AP141 -> 0 | W25: 2025 | X25: 36.5801 | Y25: 1.84655 | Z25: -1.68031 | AA25: 0 | AB25: 0 | AC25: 0.04889 | AD25: 0.00978 | AE25: -0.00978
A26: ='factor influence'!W142 -> 0 | B26: =('factor influence'!X142)/1000 -> #VALUE! | C26: =('factor influence'!Y142)/1000 -> 0 | D26: =('factor influence'!Z142)/1000 -> 0 | E26: =('factor influence'!AA142)/1000 -> 0 | F26: =('factor influence'!AB142)/1000 -> #VALUE! | G26: =('factor influence'!AC142)/1000 -> 0 | H26: =('factor influence'!AD142)/1000 -> 0 | I26: ='factor influence'!AE142 -> 0 | J26: ='factor influence'!AF142 -> toxicity influence | K26: ='factor influence'!AG142 -> 0 | L26: ='factor influence'!AH142 -> 0 | M26: ='factor influence'!AI142 -> 0 | N26: ='factor influence'!AJ142 -> toxicity influence | O26: ='factor influence'!AK142 -> 0 | P26: ='factor influence'!AL142 -> 0 | ... T26: ='factor influence'!AP142 -> 0 | W26: 2027 | X26: 41.57373 | Y26: 3.13191 | Z26: -2.59395 | AA26: 0 | AB26: 0 | AC26: 0.06127 | AD26: 0.01618 | AE26: -0.0148
A27: ='factor influence'!W143 -> 0 | B27: =('factor influence'!X143)/1000 -> #VALUE! | C27: =('factor influence'!Y143)/1000 -> #VALUE! | D27: =('factor influence'!Z143)/1000 -> #VALUE! | E27: =('factor influence'!AA143)/1000 -> 0 | F27: =('factor influence'!AB143)/1000 -> #VALUE! | G27: =('factor influence'!AC143)/1000 -> #VALUE! | H27: =('factor influence'!AD143)/1000 -> #VALUE! | I27: ='factor influence'!AE143 -> 0 | J27: ='factor influence'!AF143 -> Electronic | K27: ='factor influence'!AG143 -> Semiconductor | L27: ='factor influence'!AH143 -> Total | M27: ='factor influence'!AI143 -> 0 | N27: ='factor influence'!AJ143 -> Electronic | O27: ='factor influence'!AK143 -> Semiconductor | P27: ='factor influence'!AL143 -> Total | ... T27: ='factor influence'!AP143 -> Semiconductor | W27: 2029 | X27: 47.24972 | Y27: 4.76235 | Z27: -3.71276 | AA27: 0 | AB27: 0 | AC27: 0.07679 | AD27: 0.02546 | AE27: -0.02158
A28: ='factor influence'!W144 -> 2020 | B28: =('factor influence'!X144)/1000 -> 26.768425 | C28: =('factor influence'!Y144)/1000 -> 0.025090458 | D28: =('factor influence'!Z144)/1000 -> 26.793515 | E28: =('factor influence'!AA144)/1000 -> 0 | F28: =('factor influence'!AB144)/1000 -> 1.9283648 | G28: =('factor influence'!AC144)/1000 -> 0.010125972 | H28: =('factor influence'!AD144)/1000 -> 1.9384908 | I28: ='factor influence'!AE144 -> 0 | J28: ='factor influence'!AF144 -> 19311196 | K28: ='factor influence'!AG144 -> 101404.38 | L28: ='factor influence'!AH144 -> 19412601 | M28: ='factor influence'!AI144 -> 0 | N28: ='factor influence'!AJ144 -> 14567419 | O28: ='factor influence'!AK144 -> 76494.489 | P28: ='factor influence'!AL144 -> 14643913 | ... T28: ='factor influence'!AP144 -> 1.0928425 | W28: 2031 | X28: 53.70148 | Y28: 6.81305 | Z28: -5.07433 | AA28: 0 | AB28: 0 | AC28: 0.09624 | AD28: 0.03875 | AE28: -0.03065
A29: ='factor influence'!W145 -> 2021 | B29: =('factor influence'!X145)/1000 -> 28.220546 | C29: =('factor influence'!Y145)/1000 -> 0.027419918 | D29: =('factor influence'!Z145)/1000 -> 28.247966 | E29: =('factor influence'!AA145)/1000 -> 0 | F29: =('factor influence'!AB145)/1000 -> 2.0329738 | G29: =('factor influence'!AC145)/1000 -> 0.011066093 | H29: =('factor influence'!AD145)/1000 -> 2.0440399 | I29: ='factor influence'!AE145 -> 0 | J29: ='factor influence'!AF145 -> 20358781 | K29: ='factor influence'!AG145 -> 110819.01 | L29: ='factor influence'!AH145 -> 20469600 | M29: ='factor influence'!AI145 -> 0 | N29: ='factor influence'!AJ145 -> 15357665 | O29: ='factor influence'!AK145 -> 83596.427 | P29: ='factor influence'!AL145 -> 15441262 | ... T29: ='factor influence'!AP145 -> 1.0928425 | W29: 2033 | X29: 61.03526 | Y29: 9.37417 | Z29: -6.7225 | AA29: 0 | AB29: 0 | AC29: 0.12061 | AD29: 0.0576 | AE29: -0.04268
A30: ='factor influence'!W146 -> 2022 | B30: =('factor influence'!X146)/1000 -> 29.751441 | C30: =('factor influence'!Y146)/1000 -> 0.029965651 | D30: =('factor influence'!Z146)/1000 -> 29.781407 | E30: =('factor influence'!AA146)/1000 -> 0 | F30: =('factor influence'!AB146)/1000 -> 2.1432577 | G30: =('factor influence'!AC146)/1000 -> 0.012093496 | H30: =('factor influence'!AD146)/1000 -> 2.1553512 | I30: ='factor influence'!AE146 -> 0 | J30: ='factor influence'!AF146 -> 21463195 | K30: ='factor influence'!AG146 -> 121107.73 | L30: ='factor influence'!AH146 -> 21584302 | M30: ='factor influence'!AI146 -> 0 | N30: ='factor influence'!AJ146 -> 16190781 | O30: ='factor influence'!AK146 -> 91357.725 | P30: ='factor influence'!AL146 -> 16282138 | ... T30: ='factor influence'!AP146 -> 1.0928425 | W30: 2035 | X30: 69.37188 | Y30: 12.55369 | Z30: -8.70842 | AA30: 0 | AB30: 0 | AC30: 0.15116 | AD30: 0.08412 | AE30: -0.05857
A31: ='factor influence'!W147 -> 2023 | B31: =('factor influence'!X147)/1000 -> 31.365383 | C31: =('factor influence'!Y147)/1000 -> 0.032747736 | D31: =('factor influence'!Z147)/1000 -> 31.398131 | E31: =('factor influence'!AA147)/1000 -> 0 | F31: =('factor influence'!AB147)/1000 -> 2.2595241 | G31: =('factor influence'!AC147)/1000 -> 0.013216286 | H31: =('factor influence'!AD147)/1000 -> 2.2727404 | I31: ='factor influence'!AE147 -> 0 | J31: ='factor influence'!AF147 -> 22627520 | K31: ='factor influence'!AG147 -> 132351.67 | L31: ='factor influence'!AH147 -> 22759872 | M31: ='factor influence'!AI147 -> 0 | N31: ='factor influence'!AJ147 -> 17069091 | O31: ='factor influence'!AK147 -> 99839.602 | P31: ='factor influence'!AL147 -> 17168930 | ... T31: ='factor influence'!AP147 -> 1.0928425
A32: ='factor influence'!W148 -> 2024 | B32: =('factor influence'!X148)/1000 -> 33.066878 | C32: =('factor influence'!Y148)/1000 -> 0.035788116 | D32: =('factor influence'!Z148)/1000 -> 33.102666 | E32: =('factor influence'!AA148)/1000 -> 0 | F32: =('factor influence'!AB148)/1000 -> 2.3820977 | G32: =('factor influence'!AC148)/1000 -> 0.014443319 | H32: =('factor influence'!AD148)/1000 -> 2.396541 | I32: ='factor influence'!AE148 -> 0 | J32: ='factor influence'!AF148 -> 23855007 | K32: ='factor influence'!AG148 -> 144639.52 | L32: ='factor influence'!AH148 -> 23999647 | M32: ='factor influence'!AI148 -> 0 | N32: ='factor influence'!AJ148 -> 17995047 | O32: ='factor influence'!AK148 -> 109108.96 | P32: ='factor influence'!AL148 -> 18104156 | ... T32: ='factor influence'!AP148 -> 1.0928425
A33: ='factor influence'!W149 -> 2025 | B33: =('factor influence'!X149)/1000 -> 34.860674 | C33: =('factor influence'!Y149)/1000 -> 0.039110773 | D33: =('factor influence'!Z149)/1000 -> 34.899785 | E33: =('factor influence'!AA149)/1000 -> 0 | F33: =('factor influence'!AB149)/1000 -> 2.5113206 | G33: =('factor influence'!AC149)/1000 -> 0.015784272 | H33: =('factor influence'!AD149)/1000 -> 2.5271049 | I33: ='factor influence'!AE149 -> 0 | J33: ='factor influence'!AF149 -> 25149082 | K33: ='factor influence'!AG149 -> 158068.21 | L33: ='factor influence'!AH149 -> 25307151 | M33: ='factor influence'!AI149 -> 0 | N33: ='factor influence'!AJ149 -> 18971234 | O33: ='factor influence'!AK149 -> 119238.9 | P33: ='factor influence'!AL149 -> 19090473 | ... T33: ='factor influence'!AP149 -> 1.149
A34: ='factor influence'!W150 -> 2026 | B34: =('factor influence'!X150)/1000 -> 36.840761 | C34: =('factor influence'!Y150)/1000 -> 0.042630743 | D34: =('factor influence'!Z150)/1000 -> 36.883391 | E34: =('factor influence'!AA150)/1000 -> 0 | F34: =('factor influence'!AB150)/1000 -> 2.6539636 | G34: =('factor influence'!AC150)/1000 -> 0.017204857 | H34: =('factor influence'!AD150)/1000 -> 2.6711685 | I34: ='factor influence'!AE150 -> 0 | J34: ='factor influence'!AF150 -> 26577550 | K34: ='factor influence'!AG150 -> 172294.35 | L34: ='factor influence'!AH150 -> 26749845 | M34: ='factor influence'!AI150 -> 0 | N34: ='factor influence'!AJ150 -> 20048800 | O34: ='factor influence'!AK150 -> 129970.4 | P34: ='factor influence'!AL150 -> 20178770 | ... T34: ='factor influence'!AP150 -> 1.149
A35: ='factor influence'!W151 -> 2027 | B35: =('factor influence'!X151)/1000 -> 38.933316 | C35: =('factor influence'!Y151)/1000 -> 0.04646751 | D35: =('factor influence'!Z151)/1000 -> 38.979783 | E35: =('factor influence'!AA151)/1000 -> 0 | F35: =('factor influence'!AB151)/1000 -> 2.8047088 | G35: =('factor influence'!AC151)/1000 -> 0.018753294 | H35: =('factor influence'!AD151)/1000 -> 2.8234621 | I35: ='factor influence'!AE151 -> 0 | J35: ='factor influence'!AF151 -> 28087155 | K35: ='factor influence'!AG151 -> 187800.84 | L35: ='factor influence'!AH151 -> 28274956 | M35: ='factor influence'!AI151 -> 0 | N35: ='factor influence'!AJ151 -> 21187572 | O35: ='factor influence'!AK151 -> 141667.74 | P35: ='factor influence'!AL151 -> 21329239 | ... T35: ='factor influence'!AP151 -> 1.149
A36: ='factor influence'!W152 -> 2028 | B36: =('factor influence'!X152)/1000 -> 41.144728 | C36: =('factor influence'!Y152)/1000 -> 0.050649586 | D36: =('factor influence'!Z152)/1000 -> 41.195378 | E36: =('factor influence'!AA152)/1000 -> 0 | F36: =('factor influence'!AB152)/1000 -> 2.9640162 | G36: =('factor influence'!AC152)/1000 -> 0.02044109 | H36: =('factor influence'!AD152)/1000 -> 2.9844573 | I36: ='factor influence'!AE152 -> 0 | J36: ='factor influence'!AF152 -> 29682506 | K36: ='factor influence'!AG152 -> 204702.92 | L36: ='factor influence'!AH152 -> 29887208 | M36: ='factor influence'!AI152 -> 0 | N36: ='factor influence'!AJ152 -> 22391026 | O36: ='factor influence'!AK152 -> 154417.84 | P36: ='factor influence'!AL152 -> 22545443 | ... T36: ='factor influence'!AP152 -> 1.149
A37: ='factor influence'!W153 -> 2029 | B37: =('factor influence'!X153)/1000 -> 43.481749 | C37: =('factor influence'!Y153)/1000 -> 0.055208049 | D37: =('factor influence'!Z153)/1000 -> 43.536957 | E37: =('factor influence'!AA153)/1000 -> 0 | F37: =('factor influence'!AB153)/1000 -> 3.1323724 | G37: =('factor influence'!AC153)/1000 -> 0.022280789 | H37: =('factor influence'!AD153)/1000 -> 3.1546532 | I37: ='factor influence'!AE153 -> 0 | J37: ='factor influence'!AF153 -> 31368472 | K37: ='factor influence'!AG153 -> 223126.18 | L37: ='factor influence'!AH153 -> 31591598 | M37: ='factor influence'!AI153 -> 0 | N37: ='factor influence'!AJ153 -> 23662836 | O37: ='factor influence'!AK153 -> 168315.44 | P37: ='factor influence'!AL153 -> 23831151 | ... T37: ='factor influence'!AP153 -> 1.149
A38: ='factor influence'!W154 -> 2030 | B38: =('factor influence'!X154)/1000 -> 45.951512 | C38: =('factor influence'!Y154)/1000 -> 0.060176773 | D38: =('factor influence'!Z154)/1000 -> 46.011689 | E38: =('factor influence'!AA154)/1000 -> 0 | F38: =('factor influence'!AB154)/1000 -> 3.3102911 | G38: =('factor influence'!AC154)/1000 -> 0.02428606 | H38: =('factor influence'!AD154)/1000 -> 3.3345772 | I38: ='factor influence'!AE154 -> 0 | J38: ='factor influence'!AF154 -> 33150201 | K38: ='factor influence'!AG154 -> 243207.54 | L38: ='factor influence'!AH154 -> 33393409 | M38: ='factor influence'!AI154 -> 0 | N38: ='factor influence'!AJ154 -> 25006885 | O38: ='factor influence'!AK154 -> 183463.83 | P38: ='factor influence'!AL154 -> 25190349 | ... T38: ='factor influence'!AP154 -> 1.149
A39: ='factor influence'!W155 -> 2031 | B39: =('factor influence'!X155)/1000 -> 48.561558 | C39: =('factor influence'!Y155)/1000 -> 0.065592683 | D39: =('factor influence'!Z155)/1000 -> 48.627151 | E39: =('factor influence'!AA155)/1000 -> 0 | F39: =('factor influence'!AB155)/1000 -> 3.4983157 | G39: =('factor influence'!AC155)/1000 -> 0.026471805 | H39: =('factor influence'!AD155)/1000 -> 3.5247875 | I39: ='factor influence'!AE155 -> 0 | J39: ='factor influence'!AF155 -> 35033132 | K39: ='factor influence'!AG155 -> 265096.22 | L39: ='factor influence'!AH155 -> 35298229 | M39: ='factor influence'!AI155 -> 0 | N39: ='factor influence'!AJ155 -> 26427276 | O39: ='factor influence'!AK155 -> 199975.58 | P39: ='factor influence'!AL155 -> 26627252 | ... T39: ='factor influence'!AP155 -> 1.149 | W39: 2025 | X39: 36.5801 | Y39: 1.84655 | Z39: -1.68031 | AA39: 0 | AB39: 0 | AC39: 0.04889 | AD39: 0.00978 | AE39: -0.00978
A40: ='factor influence'!W156 -> 2032 | B40: =('factor influence'!X156)/1000 -> 51.319855 | C40: =('factor influence'!Y156)/1000 -> 0.071496024 | D40: =('factor influence'!Z156)/1000 -> 51.391351 | E40: =('factor influence'!AA156)/1000 -> 0 | F40: =('factor influence'!AB156)/1000 -> 3.69702 | G40: =('factor influence'!AC156)/1000 -> 0.028854267 | H40: =('factor influence'!AD156)/1000 -> 3.7258742 | I40: ='factor influence'!AE156 -> 0 | J40: ='factor influence'!AF156 -> 37023014 | K40: ='factor influence'!AG156 -> 288954.88 | L40: ='factor influence'!AH156 -> 37311969 | M40: ='factor influence'!AI156 -> 0 | N40: ='factor influence'!AJ156 -> 27928345 | O40: ='factor influence'!AK156 -> 217973.38 | P40: ='factor influence'!AL156 -> 28146319 | ... T40: ='factor influence'!AP156 -> 1.149 | W40: 2026 | X40: 38.997 | Y40: 2.45028 | Z40: -2.11361 | AA40: 0 | AB40: 0 | AC40: 0.05473 | AD40: 0.01268 | AE40: -0.0121
A41: ='factor influence'!W157 -> 2033 | B41: =('factor influence'!X157)/1000 -> 54.234822 | C41: =('factor influence'!Y157)/1000 -> 0.077930666 | D41: =('factor influence'!Z157)/1000 -> 54.312753 | E41: =('factor influence'!AA157)/1000 -> 0 | F41: =('factor influence'!AB157)/1000 -> 3.9070107 | G41: =('factor influence'!AC157)/1000 -> 0.031451151 | H41: =('factor influence'!AD157)/1000 -> 3.9384619 | I41: ='factor influence'!AE157 -> 0 | J41: ='factor influence'!AF157 -> 39125922 | K41: ='factor influence'!AG157 -> 314960.82 | L41: ='factor influence'!AH157 -> 39440882 | M41: ='factor influence'!AI157 -> 0 | N41: ='factor influence'!AJ157 -> 29514675 | O41: ='factor influence'!AK157 -> 237590.98 | P41: ='factor influence'!AL157 -> 29752266 | ... T41: ='factor influence'!AP157 -> 1.149 | W41: 2027 | X41: 41.57373 | Y41: 3.13191 | Z41: -2.59395 | AA41: 0 | AB41: 0 | AC41: 0.06127 | AD41: 0.01618 | AE41: -0.0148
A42: ='factor influence'!W158 -> 2034 | B42: =('factor influence'!X158)/1000 -> 57.31536 | C42: =('factor influence'!Y158)/1000 -> 0.084944426 | D42: =('factor influence'!Z158)/1000 -> 57.400305 | E42: =('factor influence'!AA158)/1000 -> 0 | F42: =('factor influence'!AB158)/1000 -> 4.1289289 | G42: =('factor influence'!AC158)/1000 -> 0.034281755 | H42: =('factor influence'!AD158)/1000 -> 4.1632107 | I42: ='factor influence'!AE158 -> 0 | J42: ='factor influence'!AF158 -> 41348274 | K42: ='factor influence'!AG158 -> 343307.29 | L42: ='factor influence'!AH158 -> 41691581 | M42: ='factor influence'!AI158 -> 0 | N42: ='factor influence'!AJ158 -> 31191109 | O42: ='factor influence'!AK158 -> 258974.17 | P42: ='factor influence'!AL158 -> 31450083 | ... T42: ='factor influence'!AP158 -> 1.149 | W42: 2028 | X42: 44.32087 | Y42: 3.89962 | Z42: -3.1255 | AA42: 0 | AB42: 0 | AC42: 0.06859 | AD42: 0.0204 | AE42: -0.01794
A43: ='factor influence'!W159 -> 2035 | B43: =('factor influence'!X159)/1000 -> 60.570873 | C43: =('factor influence'!Y159)/1000 -> 0.092589424 | D43: =('factor influence'!Z159)/1000 -> 60.663462 | E43: =('factor influence'!AA159)/1000 -> 0 | F43: =('factor influence'!AB159)/1000 -> 4.3634521 | G43: =('factor influence'!AC159)/1000 -> 0.037367113 | H43: =('factor influence'!AD159)/1000 -> 4.4008192 | I43: ='factor influence'!AE159 -> 0 | J43: ='factor influence'!AF159 -> 43696856 | K43: ='factor influence'!AG159 -> 374204.95 | L43: ='factor influence'!AH159 -> 44071061 | M43: ='factor influence'!AI159 -> 0 | N43: ='factor influence'!AJ159 -> 32962764 | O43: ='factor influence'!AK159 -> 282281.85 | P43: ='factor influence'!AL159 -> 33245046 | ... T43: ='factor influence'!AP159 -> 1.149 | W43: 2029 | X43: 47.24972 | Y43: 4.76235 | Z43: -3.71276 | AA43: 0 | AB43: 0 | AC43: 0.07679 | AD43: 0.02546 | AE43: -0.02158
A44: ='factor influence'!W160 -> 0 | B44: =('factor influence'!X160)/1000 -> 0 | C44: =('factor influence'!Y160)/1000 -> 0 | D44: =('factor influence'!Z160)/1000 -> 0 | E44: =('factor influence'!AA160)/1000 -> 0 | F44: =('factor influence'!AB160)/1000 -> 0 | G44: =('factor influence'!AC160)/1000 -> 0 | H44: =('factor influence'!AD160)/1000 -> 0 | I44: ='factor influence'!AE160 -> 0 | J44: ='factor influence'!AF160 -> 0 | K44: ='factor influence'!AG160 -> 0 | L44: ='factor influence'!AH160 -> 0 | M44: ='factor influence'!AI160 -> 0 | N44: ='factor influence'!AJ160 -> 0 | O44: ='factor influence'!AK160 -> 0 | P44: ='factor influence'!AL160 -> 0 | ... T44: ='factor influence'!AP160 -> 0 | W44: 2030 | X44: 50.37231 | Y44: 5.72992 | Z44: -4.36062 | AA44: 0 | AB44: 0 | AC44: 0.08597 | AD44: 0.03152 | AE44: -0.02579
A45: ='factor influence'!W161 -> 0 | B45: =('factor influence'!X161)/1000 -> 0 | C45: =('factor influence'!Y161)/1000 -> 0 | D45: =('factor influence'!Z161)/1000 -> 0 | E45: =('factor influence'!AA161)/1000 -> 0 | F45: =('factor influence'!AB161)/1000 -> 0 | G45: =('factor influence'!AC161)/1000 -> 0 | H45: =('factor influence'!AD161)/1000 -> 0 | I45: ='factor influence'!AE161 -> 0 | J45: ='factor influence'!AF161 -> 0 | K45: ='factor influence'!AG161 -> 0 | L45: ='factor influence'!AH161 -> 0 | M45: ='factor influence'!AI161 -> 0 | N45: ='factor influence'!AJ161 -> 0 | O45: ='factor influence'!AK161 -> 0 | P45: ='factor influence'!AL161 -> 0 | ... T45: ='factor influence'!AP161 -> 0 | W45: 2031 | X45: 53.70148 | Y45: 6.81305 | Z45: -5.07433 | AA45: 0 | AB45: 0 | AC45: 0.09624 | AD45: 0.03875 | AE45: -0.03065
...

Sheet factor influence
B3: Basic, 6.6%+14.9% | X3: -0.15 | AT3: 40
B4: Results | K4: PFOS as basic | O4: PFOA Basic | S4: CAGR | X4: Results | AG4: PFOS as basic | AK4: PFOA Basic | AO4: CAGR | AT4: Results | BC4: PFOS as basic | BG4: PFOA Basic | BK4: CAGR
C5: Use amount | G5: Emission to wastewater | K5: toxicity influence | O5: toxicity influence | T5: Use amount | Y5: Use amount | AC5: Emission to wastewater | AG5: toxicity influence | AK5: toxicity influence | AP5: Use amount | AU5: Use amount | AY5: Emission to wastewater | BC5: toxicity influence | BG5: toxicity influence | BL5: Use amount
C6: Electronic | D6: Semiconductor | E6: Total | G6: Electronic | H6: Semiconductor | I6: Total | K6: Electronic | L6: Semiconductor | M6: Total | O6: Electronic | P6: Semiconductor | Q6: Total | T6: Electronic | U6: Semiconductor | Y6: Electronic | Z6: Semiconductor | AA6: Total | AC6: Electronic | AD6: Semiconductor | AE6: Total | AG6: Electronic | AH6: Semiconductor | AI6: Total | AK6: Electronic | AL6: Semiconductor | AM6: Total | AP6: Electronic | AQ6: Semiconductor | AU6: Electronic | AV6: Semiconductor | AW6: Total | AY6: Electronic | AZ6: Semiconductor | BA6: Total | BC6: Electronic | BD6: Semiconductor | BE6: Total | BG6: Electronic | BH6: Semiconductor | BI6: Total | BL6: Electronic | BM6: Semiconductor
B7: 2020 | C7: ='semicondutcor&electronic'!$B$17 -> 28051.177 | D7: ='semicondutcor&electronic'!$B$11 -> 31.363072 | E7: =C7+D7 -> 28082.54 | G7: =C7*'semicondutcor&electronic'!$D$16*'semicondutcor&electronic'!$E$16 -> 2796.9172 | H7: =D7*'semicondutcor&electronic'!$E$16 -> 14.891136 | I7: =G7+H7 -> 2811.8084 | K7: =G7/'PFAS toxicity'!$L$4*'PFAS toxicity'!$H$3 -> 28009128 | L7: =H7/'PFAS toxicity'!$L$4*'PFAS toxicity'!$H$3 -> 149124.09 | M7: =K7+L7 -> 28158252 | O7: =G7/'PFAS toxicity'!$L$4*'PFAS toxicity'!$I$3 -> 21128712 | P7: =H7/'PFAS toxicity'!$L$4*'PFAS toxicity'!$I$3 -> 112491.9 | Q7: =O7+P7 -> 21241204 | S7: 2020 | T7: ='semicondutcor&electronic'!$A$36^(1/4) -> 1.0542475 | U7: ='semicondutcor&electronic'!$A$35^(1/4) -> 1.0928425 | X7: 2020 | Y7: ='semicondutcor&electronic'!$B$17 -> 28051.177 | Z7: ='semicondutcor&electronic'!$B$11 -> 31.363072 | AA7: =Y7+Z7 -> 28082.54 | AC7: =Y7*'semicondutcor&electronic'!$D$16*'semicondutcor&electronic'!$E$17 -> 2377.3796 | AD7: =Z7*'semicondutcor&electronic'!$E$17 -> 12.657466 | AE7: =AC7+AD7 -> 2390.0371 | AG7: =AC7/'PFAS toxicity'!$L$4*'PFAS toxicity'!$H$3 -> 23807759 | AH7: =AD7/'PFAS toxicity'!$L$4*'PFAS toxicity'!$H$3 -> 126755.48 | AI7: =AG7+AH7 -> 23934514 | AK7: =AC7/'PFAS toxicity'!$L$4*'PFAS toxicity'!$I$3 -> 17959405 | AL7: =AD7/'PFAS toxicity'!$L$4*'PFAS toxicity'!$I$3 -> 95618.112 | AM7: =AK7+AL7 -> 18055023 | AO7: 2020 | AP7: ='semicondutcor&electronic'!$A$36^(1/4) -> 1.0542475 | AQ7: ='semicondutcor&electronic'!$A$35^(1/4) -> 1.0928425 | AT7: 2020 | AU7: ='semicondutcor&electronic'!$B$17 -> 28051.177 | AV7: ='semicondutcor&electronic'!$B$12 -> 25.090458 | AW7: =AU7+AV7 -> 28076.267 | AY7: =AU7*'semicondutcor&electronic'!$D$16*'semicondutcor&electronic'!$E$16 -> 2796.9172 | AZ7: =AV7*'semicondutcor&electronic'!$E$16 -> 11.912909 | BA7: =AY7+AZ7 -> 2808.8301 | BC7: =AY7/'PFAS toxicity'!$L$4*'PFAS toxicity'!$H$3 -> 28009128 | BD7: =AZ7/'PFAS toxicity'!$L$4*'PFAS toxicity'!$H$3 -> 119299.27 | BE7: =BC7+BD7 -> 28128427 | BG7: =AY7/'PFAS toxicity'!$L$4*'PFAS toxicity'!$I$3 -> 21128712 | BH7: =AZ7/'PFAS toxicity'!$L$4*'PFAS toxicity'!$I$3 -> 89993.517 | BI7: =BG7+BH7 -> 21218705 | BK7: 2020 | BL7: ='semicondutcor&electronic'!$A$36^(1/4) -> 1.0542475 | BM7: ='semicondutcor&electronic'!$A$35^(1/4) -> 1.0928425
B8: 2021 | C8: =C7*T7 -> 29572.884 | D8: =D7*U7 -> 34.274897 | E8: =C8+D8 -> 29607.159 | G8: =C8*'semicondutcor&electronic'!$D$16*'semicondutcor&electronic'!$E$16 -> 2948.6431 | H8: =D8*'semicondutcor&electronic'!$E$16 -> 16.273666 | I8: =G8+H8 -> 2964.9167 | K8: =G8/'PFAS toxicity'!$L$4*'PFAS toxicity'!$H$3 -> 29528554 | L8: =H8/'PFAS toxicity'!$L$4*'PFAS toxicity'!$H$3 -> 162969.14 | M8: =K8+L8 -> 29691523 | O8: =G8/'PFAS toxicity'!$L$4*'PFAS toxicity'!$I$3 -> 22274892 | P8: =H8/'PFAS toxicity'!$L$4*'PFAS toxicity'!$I$3 -> 122935.92 | Q8: =O8+P8 -> 22397828 | S8: 2021 | T8: ='semicondutcor&electronic'!$A$36^(1/4) -> 1.0542475 | U8: ='semicondutcor&electronic'!$A$35^(1/4) -> 1.0928425 | X8: 2021 | Y8: =Y7*AP7 -> 29572.884 | Z8: =Z7*AQ7 -> 34.274897 | AA8: =Y8+Z8 -> 29607.159 | AC8: =Y8*'semicondutcor&electronic'!$D$16*'semicondutcor&electronic'!$E$17 -> 2506.3466 | AD8: =Z8*'semicondutcor&electronic'!$E$17 -> 13.832616 | AE8: =AC8+AD8 -> 2520.1792 | AG8: =AC8/'PFAS toxicity'!$L$4*'PFAS toxicity'!$H$3 -> 25099271 | AH8: =AD8/'PFAS toxicity'!$L$4*'PFAS toxicity'!$H$3 -> 138523.77 | AI8: =AG8+AH8 -> 25237795 | AK8: =AC8/'PFAS toxicity'!$L$4*'PFAS toxicity'!$I$3 -> 18933658 | AL8: =AD8/'PFAS toxicity'!$L$4*'PFAS toxicity'!$I$3 -> 104495.53 | AM8: =AK8+AL8 -> 19038154 | AO8: 2021 | AP8: ='semicondutcor&electronic'!$A$36^(1/4) -> 1.0542475 | AQ8: ='semicondutcor&electronic'!$A$35^(1/4) -> 1.0928425 | AT8: 2021 | AU8: =AU7*BL7 -> 29572.884 | AV8: =AV7*BM7 -> 27.419918 | AW8: =AU8+AV8 -> 29600.304 | AY8: =AU8*'semicondutcor&electronic'!$D$16*'semicondutcor&electronic'!$E$16 -> 2948.6431 | AZ8: =AV8*'semicondutcor&electronic'!$E$16 -> 13.018933 | BA8: =AY8+AZ8 -> 2961.662 | BC8: =AY8/'PFAS toxicity'!$L$4*'PFAS toxicity'!$H$3 -> 29528554 | BD8: =AZ8/'PFAS toxicity'!$L$4*'PFAS toxicity'!$H$3 -> 130375.31 | BE8: =BC8+BD8 -> 29658930 | BG8: =AY8/'PFAS toxicity'!$L$4*'PFAS toxicity'!$I$3 -> 22274892 | BH8: =AZ8/'PFAS toxicity'!$L$4*'PFAS toxicity'!$I$3 -> 98348.737 | BI8: =BG8+BH8 -> 22373241 | BK8: 2021 | BL8: ='semicondutcor&electronic'!$A$36^(1/4) -> 1.0542475 | BM8: ='semicondutcor&electronic'!$A$35^(1/4) -> 1.0928425
B9: 2022 | C9: =C8*T8 -> 31177.14 | D9: =D8*U8 -> 37.457063 | E9: =C9+D9 -> 31214.597 | G9: =C9*'semicondutcor&electronic'!$D$16*'semicondutcor&electronic'!$E$16 -> 3108.5997 | H9: =D9*'semicondutcor&electronic'!$E$16 -> 17.784553 | I9: =G9+H9 -> 3126.3842 | K9: =G9/'PFAS toxicity'!$L$4*'PFAS toxicity'!$H$3 -> 31130405 | L9: =H9/'PFAS toxicity'!$L$4*'PFAS toxicity'!$H$3 -> 178099.6 | M9: =K9+L9 -> 31308505 | O9: =G9/'PFAS toxicity'!$L$4*'PFAS toxicity'!$I$3 -> 23483250 | P9: =H9/'PFAS toxicity'!$L$4*'PFAS toxicity'!$I$3 -> 134349.6 | Q9: =O9+P9 -> 23617600 | S9: 2022 | T9: ='semicondutcor&electronic'!$A$36^(1/4) -> 1.0542475 | U9: ='semicondutcor&electronic'!$A$35^(1/4) -> 1.0928425 | X9: 2022 | Y9: =Y8*AP8 -> 31177.14 | Z9: =Z8*AQ8 -> 37.457063 | AA9: =Y9+Z9 -> 31214.597 | AC9: =Y9*'semicondutcor&electronic'!$D$16*'semicondutcor&electronic'!$E$17 -> 2642.3097 | AD9: =Z9*'semicondutcor&electronic'!$E$17 -> 15.11687 | AE9: =AC9+AD9 -> 2657.4266 | AG9: =AC9/'PFAS toxicity'!$L$4*'PFAS toxicity'!$H$3 -> 26460845 | AH9: =AD9/'PFAS toxicity'!$L$4*'PFAS toxicity'!$H$3 -> 151384.66 | AI9: =AG9+AH9 -> 26612229 | AK9: =AC9/'PFAS toxicity'!$L$4*'PFAS toxicity'!$I$3 -> 19960763 | AL9: =AD9/'PFAS toxicity'!$L$4*'PFAS toxicity'!$I$3 -> 114197.16 | AM9: =AK9+AL9 -> 20074960 | AO9: 2022 | AP9: ='semicondutcor&electronic'!$A$36^(1/4) -> 1.0542475 | AQ9: ='semicondutcor&electronic'!$A$35^(1/4) -> 1.0928425 | AT9: 2022 | AU9: =AU8*BL8 -> 31177.14 | AV9: =AV8*BM8 -> 29.965651 | AW9: =AU9+AV9 -> 31207.105 | AY9: =AU9*'semicondutcor&electronic'!$D$16*'semicondutcor&electronic'!$E$16 -> 3108.5997 | AZ9: =AV9*'semicondutcor&electronic'!$E$16 -> 14.227643 | BA9: =AY9+AZ9 -> 3122.8273 | BC9: =AY9/'PFAS toxicity'!$L$4*'PFAS toxicity'!$H$3 -> 31130405 | BD9: =AZ9/'PFAS toxicity'!$L$4*'PFAS toxicity'!$H$3 -> 142479.68 | BE9: =BC9+BD9 -> 31272885 | BG9: =AY9/'PFAS toxicity'!$L$4*'PFAS toxicity'!$I$3 -> 23483250 | BH9: =AZ9/'PFAS toxicity'!$L$4*'PFAS toxicity'!$I$3 -> 107479.68 | BI9: =BG9+BH9 -> 23590730 | BK9: 2022 | BL9: ='semicondutcor&electronic'!$A$36^(1/4) -> 1.0542475 | BM9: ='semicondutcor&electronic'!$A$35^(1/4) -> 1.0928425
B10: 2023 | C10: =C9*T9 -> 32868.423 | D10: =D9*U9 -> 40.93467 | E10: =C10+D10 -> 32909.357 | G10: =C10*'semicondutcor&electronic'!$D$16*'semicondutcor&electronic'!$E$16 -> 3277.2336 | H10: =D10*'semicondutcor&electronic'!$E$16 -> 19.435715 | I10: =G10+H10 -> 3296.6693 | K10: =G10/'PFAS toxicity'!$L$4*'PFAS toxicity'!$H$3 -> 32819153 | L10: =H10/'PFAS toxicity'!$L$4*'PFAS toxicity'!$H$3 -> 194634.8 | M10: =K10+L10 -> 33013788 | O10: =G10/'PFAS toxicity'!$L$4*'PFAS toxicity'!$I$3 -> 24757159 | P10: =H10/'PFAS toxicity'!$L$4*'PFAS toxicity'!$I$3 -> 146822.94 | Q10: =O10+P10 -> 24903982 | S10: 2023 | T10: ='semicondutcor&electronic'!$A$36^(1/4) -> 1.0542475 | U10: ='semicondutcor&electronic'!$A$35^(1/4) -> 1.0928425 | X10: 2023 | Y10: =Y9*AP9 -> 32868.423 | Z10: =Z9*AQ9 -> 40.93467 | AA10: =Y10+Z10 -> 32909.357 | AC10: =Y10*'semicondutcor&electronic'!$D$16*'semicondutcor&electronic'!$E$17 -> 2785.6485 | AD10: =Z10*'semicondutcor&electronic'!$E$17 -> 16.520358 | AE10: =AC10+AD10 -> 2802.1689 | AG10: =AC10/'PFAS toxicity'!$L$4*'PFAS toxicity'!$H$3 -> 27896280 | AH10: =AD10/'PFAS toxicity'!$L$4*'PFAS toxicity'!$H$3 -> 165439.58 | AI10: =AG10+AH10 -> 28061720 | AK10: =AC10/'PFAS toxicity'!$L$4*'PFAS toxicity'!$I$3 -> 21043585 | AL10: =AD10/'PFAS toxicity'!$L$4*'PFAS toxicity'!$I$3 -> 124799.5 | AM10: =AK10+AL10 -> 21168384 | AO10: 2023 | AP10: ='semicondutcor&electronic'!$A$36^(1/4) -> 1.0542475 | AQ10: ='semicondutcor&electronic'!$A$35^(1/4) -> 1.0928425 | AT10: 2023 | AU10: =AU9*BL9 -> 32868.423 | AV10: =AV9*BM9 -> 32.747736 | AW10: =AU10+AV10 -> 32901.17 | AY10: =AU10*'semicondutcor&electronic'!$D$16*'semicondutcor&electronic'!$E$16 -> 3277.2336 | AZ10: =AV10*'semicondutcor&electronic'!$E$16 -> 15.548572 | BA10: =AY10+AZ10 -> 3292.7821 | BC10: =AY10/'PFAS toxicity'!$L$4*'PFAS toxicity'!$H$3 -> 32819153 | BD10: =AZ10/'PFAS toxicity'!$L$4*'PFAS toxicity'!$H$3 -> 155707.84 | BE10: =BC10+BD10 -> 32974861 | BG10: =AY10/'PFAS toxicity'!$L$4*'PFAS toxicity'!$I$3 -> 24757159 | BH10: =AZ10/'PFAS toxicity'!$L$4*'PFAS toxicity'!$I$3 -> 117458.36 | BI10: =BG10+BH10 -> 24874617 | BK10: 2023 | BL10: ='semicondutcor&electronic'!$A$36^(1/4) -> 1.0542475 | BM10: ='semicondutcor&electronic'!$A$35^(1/4) -> 1.0928425
B11: 2024 | C11: =C10*T10 -> 34651.453 | D11: =D10*U10 -> 44.735145 | E11: =C11+D11 -> 34696.189 | G11: =C11*'semicondutcor&electronic'!$D$16*'semicondutcor&electronic'!$E$16 -> 3455.0154 | H11: =D11*'semicondutcor&electronic'!$E$16 -> 21.240175 | I11: =G11+H11 -> 3476.2556 | K11: =G11/'PFAS toxicity'!$L$4*'PFAS toxicity'!$H$3 -> 34599511 | L11: =H11/'PFAS toxicity'!$L$4*'PFAS toxicity'!$H$3 -> 212705.18 | M11: =K11+L11 -> 34812216 | O11: =G11/'PFAS toxicity'!$L$4*'PFAS toxicity'!$I$3 -> 26100173 | P11: =H11/'PFAS toxicity'!$L$4*'PFAS toxicity'!$I$3 -> 160454.35 | Q11: =O11+P11 -> 26260628 | S11: 2024 | T11: ='semicondutcor&electronic'!$A$36^(1/4) -> 1.0542475 | U11: ='semicondutcor&electronic'!$A$35^(1/4) -> 1.0928425 | X11: 2024 | Y11: =Y10*AP10 -> 34651.453 | Z11: =Z10*AQ10 -> 44.735145 | AA11: =Y11+Z11 -> 34696.189 | AC11: =Y11*'semicondutcor&electronic'!$D$16*'semicondutcor&electronic'!$E$17 -> 2936.7631 | AD11: =Z11*'semicondutcor&electronic'!$E$17 -> 18.054149 | AE11: =AC11+AD11 -> 2954.8172 | AG11: =AC11/'PFAS toxicity'!$L$4*'PFAS toxicity'!$H$3 -> 29409585 | AH11: =AD11/'PFAS toxicity'!$L$4*'PFAS toxicity'!$H$3 -> 180799.4 | AI11: =AG11+AH11 -> 29590384 | AK11: =AC11/'PFAS toxicity'!$L$4*'PFAS toxicity'!$I$3 -> 22185147 | AL11: =AD11/'PFAS toxicity'!$L$4*'PFAS toxicity'!$I$3 -> 136386.2 | AM11: =AK11+AL11 -> 22321534 | AO11: 2024 | AP11: ='semicondutcor&electronic'!$A$36^(1/4) -> 1.0542475 | AQ11: ='semicondutcor&electronic'!$A$35^(1/4) -> 1.0928425 | AT11: 2024 | AU11: =AU10*BL10 -> 34651.453 | AV11: =AV10*BM10 -> 35.788116 | AW11: =AU11+AV11 -> 34687.242 | AY11: =AU11*'semicondutcor&electronic'!$D$16*'semicondutcor&electronic'!$E$16 -> 3455.0154 | AZ11: =AV11*'semicondutcor&electronic'!$E$16 -> 16.99214 | BA11: =AY11+AZ11 -> 3472.0075 | BC11: =AY11/'PFAS toxicity'!$L$4*'PFAS toxicity'!$H$3 -> 34599511 | BD11: =AZ11/'PFAS toxicity'!$L$4*'PFAS toxicity'!$H$3 -> 170164.14 | BE11: =BC11+BD11 -> 34769675 | BG11: =AY11/'PFAS toxicity'!$L$4*'PFAS toxicity'!$I$3 -> 26100173 | BH11: =AZ11/'PFAS toxicity'!$L$4*'PFAS toxicity'!$I$3 -> 128363.48 | BI11: =BG11+BH11 -> 26228537 | BK11: 2024 | BL11: ='semicondutcor&electronic'!$A$36^(1/4) -> 1.0542475 | BM11: ='semicondutcor&electronic'!$A$35^(1/4) -> 1.0928425
B12: 2025 | C12: =C11*T11 -> 36531.209 | D12: =D11*U11 -> 48.888467 | E12: =C12+D12 -> 36580.098 | G12: =C12*'semicondutcor&electronic'!$D$16*'semicondutcor&electronic'!$E$16 -> 3642.4414 | H12: =D12*'semicondutcor&electronic'!$E$16 -> 23.212165 | I12: =G12+H12 -> 3665.6536 | K12: =G12/'PFAS toxicity'!$L$4*'PFAS toxicity'!$H$3 -> 36476449 | L12: =H12/'PFAS toxicity'!$L$4*'PFAS toxicity'!$H$3 -> 232453.25 | M12: =K12+L12 -> 36708903 | O12: =G12/'PFAS toxicity'!$L$4*'PFAS toxicity'!$I$3 -> 27516043 | P12: =H12/'PFAS toxicity'!$L$4*'PFAS toxicity'!$I$3 -> 175351.33 | Q12: =O12+P12 -> 27691395 | S12: 2025 | T12: =1+'semicondutcor&electronic'!$A$27 -> 1.066 | U12: =1+'semicondutcor&electronic'!$A$29 -> 1.1195 | X12: 2025 | Y12: =Y11*AP11 -> 36531.209 | Z12: =Z11*AQ11 -> 48.888467 | AA12: =Y12+Z12 -> 36580.098 | AC12: =Y12*'semicondutcor&electronic'!$D$16*'semicondutcor&electronic'!$E$17 -> 3096.0752 | AD12: =Z12*'semicondutcor&electronic'!$E$17 -> 19.73034 | AE12: =AC12+AD12 -> 3115.8056 | AG12: =AC12/'PFAS toxicity'!$L$4*'PFAS toxicity'!$H$3 -> 31004982 | AH12: =AD12/'PFAS toxicity'!$L$4*'PFAS toxicity'!$H$3 -> 197585.27 | AI12: =AG12+AH12 -> 31202567 | AK12: =AC12/'PFAS toxicity'!$L$4*'PFAS toxicity'!$I$3 -> 23388637 | AL12: =AD12/'PFAS toxicity'!$L$4*'PFAS toxicity'!$I$3 -> 149048.63 | AM12: =AK12+AL12 -> 23537685 | AO12: 2025 | AP12: =1+'semicondutcor&electronic'!$A$27 -> 1.066 | AQ12: =1+'semicondutcor&electronic'!$A$29 -> 1.1195 | AT12: 2025 | AU12: =AU11*BL11 -> 36531.209 | AV12: =AV11*BM11 -> 39.110773 | AW12: =AU12+AV12 -> 36570.32 | AY12: =AU12*'semicondutcor&electronic'!$D$16*'semicondutcor&electronic'!$E$16 -> 3642.4414 | AZ12: =AV12*'semicondutcor&electronic'!$E$16 -> 18.569732 | BA12: =AY12+AZ12 -> 3661.0112 | BC12: =AY12/'PFAS toxicity'!$L$4*'PFAS toxicity'!$H$3 -> 36476449 | BD12: =AZ12/'PFAS toxicity'!$L$4*'PFAS toxicity'!$H$3 -> 185962.6 | BE12: =BC12+BD12 -> 36662412 | BG12: =AY12/'PFAS toxicity'!$L$4*'PFAS toxicity'!$I$3 -> 27516043 | BH12: =AZ12/'PFAS toxicity'!$L$4*'PFAS toxicity'!$I$3 -> 140281.06 | BI12: =BG12+BH12 -> 27656324 | BK12: 2025 | BL12: =1+'semicondutcor&electronic'!$A$27 -> 1.066 | BM12: =1+'semicondutcor&electronic'!$A$29 -> 1.1195
B13: 2026 | C13: =C12*T12 -> 38942.269 | D13: =D12*U12 -> 54.730639 | E13: =C13+D13 -> 38997 | G13: =C13*'semicondutcor&electronic'!$D$16*'semicondutcor&electronic'!$E$16 -> 3882.8426 | H13: =D13*'semicondutcor&electronic'!$E$16 -> 25.986019 | I13: =G13+H13 -> 3908.8286 | K13: =G13/'PFAS toxicity'!$L$4*'PFAS toxicity'!$H$3 -> 38883895 | L13: =H13/'PFAS toxicity'!$L$4*'PFAS toxicity'!$H$3 -> 260231.42 | M13: =K13+L13 -> 39144126 | O13: =G13/'PFAS toxicity'!$L$4*'PFAS toxicity'!$I$3 -> 29332102 | P13: =H13/'PFAS toxicity'!$L$4*'PFAS toxicity'!$I$3 -> 196305.81 | Q13: =O13+P13 -> 29528408 | S13: 2026 | T13: =1+'semicondutcor&electronic'!$A$27 -> 1.066 | U13: =1+'semicondutcor&electronic'!$A$29 -> 1.1195 | X13: 2026 | Y13: =Y12*AP12 -> 38942.269 | Z13: =Z12*AQ12 -> 54.730639 | AA13: =Y13+Z13 -> 38997 | AC13: =Y13*'semicondutcor&electronic'!$D$16*'semicondutcor&electronic'!$E$17 -> 3300.4162 | AD13: =Z13*'semicondutcor&electronic'!$E$17 -> 22.088116 | AE13: =AC13+AD13 -> 3322.5043 | AG13: =AC13/'PFAS toxicity'!$L$4*'PFAS toxicity'!$H$3 -> 33051311 | AH13: =AD13/'PFAS toxicity'!$L$4*'PFAS toxicity'!$H$3 -> 221196.71 | AI13: =AG13+AH13 -> 33272507 | AK13: =AC13/'PFAS toxicity'!$L$4*'PFAS toxicity'!$I$3 -> 24932287 | AL13: =AD13/'PFAS toxicity'!$L$4*'PFAS toxicity'!$I$3 -> 166859.94 | AM13: =AK13+AL13 -> 25099147 | AO13: 2026 | AP13: =1+'semicondutcor&electronic'!$A$27 -> 1.066 | AQ13: =1+'semicondutcor&electronic'!$A$29 -> 1.1195 | AT13: 2026 | AU13: =AU12*BL12 -> 38942.269 | AV13: =AV12*BM12 -> 43.784511 | AW13: =AU13+AV13 -> 38986.054 | AY13: =AU13*'semicondutcor&electronic'!$D$16*'semicondutcor&electronic'!$E$16 -> 3882.8426 | AZ13: =AV13*'semicondutcor&electronic'!$E$16 -> 20.788815 | BA13: =AY13+AZ13 -> 3903.6314 | BC13: =AY13/'PFAS toxicity'!$L$4*'PFAS toxicity'!$H$3 -> 38883895 | BD13: =AZ13/'PFAS toxicity'!$L$4*'PFAS toxicity'!$H$3 -> 208185.13 | BE13: =BC13+BD13 -> 39092080 | BG13: =AY13/'PFAS toxicity'!$L$4*'PFAS toxicity'!$I$3 -> 29332102 | BH13: =AZ13/'PFAS toxicity'!$L$4*'PFAS toxicity'!$I$3 -> 157044.65 | BI13: =BG13+BH13 -> 29489147 | BK13: 2026 | BL13: =1+'semicondutcor&electronic'!$A$27 -> 1.066 | BM13: =1+'semicondutcor&electronic'!$A$29 -> 1.1195
B14: 2027 | C14: =C13*T13 -> 41512.459 | D14: =D13*U13 -> 61.27095 | E14: =C14+D14 -> 41573.73 | G14: =C14*'semicondutcor&electronic'!$D$16*'semicondutcor&electronic'!$E$16 -> 4139.1102 | H14: =D14*'semicondutcor&electronic'!$E$16 -> 29.091348 | I14: =G14+H14 -> 4168.2015 | K14: =G14/'PFAS toxicity'!$L$4*'PFAS toxicity'!$H$3 -> 41450232 | L14: =H14/'PFAS toxicity'!$L$4*'PFAS toxicity'!$H$3 -> 291329.07 | M14: =K14+L14 -> 41741561 | O14: =G14/'PFAS toxicity'!$L$4*'PFAS toxicity'!$I$3 -> 31268021 | P14: =H14/'PFAS toxicity'!$L$4*'PFAS toxicity'!$I$3 -> 219764.36 | Q14: =O14+P14 -> 31487785 | S14: 2027 | T14: =1+'semicondutcor&electronic'!$A$27 -> 1.066 | U14: =1+'semicondutcor&electronic'!$A$29 -> 1.1195 | X14: 2027 | Y14: =Y13*AP13 -> 41512.459 | Z14: =Z13*AQ13 -> 61.27095 | AA14: =Y14+Z14 -> 41573.73 | AC14: =Y14*'semicondutcor&electronic'!$D$16*'semicondutcor&electronic'!$E$17 -> 3518.2437 | AD14: =Z14*'semicondutcor&electronic'!$E$17 -> 24.727646 | AE14: =AC14+AD14 -> 3542.9713 | AG14: =AC14/'PFAS toxicity'!$L$4*'PFAS toxicity'!$H$3 -> 35232697 | AH14: =AD14/'PFAS toxicity'!$L$4*'PFAS toxicity'!$H$3 -> 247629.71 | AI14: =AG14+AH14 -> 35480327 | AK14: =AC14/'PFAS toxicity'!$L$4*'PFAS toxicity'!$I$3 -> 26577818 | AL14: =AD14/'PFAS toxicity'!$L$4*'PFAS toxicity'!$I$3 -> 186799.7 | AM14: =AK14+AL14 -> 26764618 | AO14: 2027 | AP14: =1+'semicondutcor&electronic'!$A$27 -> 1.066 | AQ14: =1+'semicondutcor&electronic'!$A$29 -> 1.1195 | AT14: 2027 | AU14: =AU13*BL13 -> 41512.459 | AV14: =AV13*BM13 -> 49.01676 | AW14: =AU14+AV14 -> 41561.476 | AY14: =AU14*'semicondutcor&electronic'!$D$16*'semicondutcor&electronic'!$E$16 -> 4139.1102 | AZ14: =AV14*'semicondutcor&electronic'!$E$16 -> 23.273079 | BA14: =AY14+AZ14 -> 4162.3833 | BC14: =AY14/'PFAS toxicity'!$L$4*'PFAS toxicity'!$H$3 -> 41450232 | BD14: =AZ14/'PFAS toxicity'!$L$4*'PFAS toxicity'!$H$3 -> 233063.26 | BE14: =BC14+BD14 -> 41683295 | BG14: =AY14/'PFAS toxicity'!$L$4*'PFAS toxicity'!$I$3 -> 31268021 | BH14: =AZ14/'PFAS toxicity'!$L$4*'PFAS toxicity'!$I$3 -> 175811.49 | BI14: =BG14+BH14 -> 31443832 | BK14: 2027 | BL14: =1+'semicondutcor&electronic'!$A$27 -> 1.066 | BM14: =1+'semicondutcor&electronic'!$A$29 -> 1.1195
B15: 2028 | C15: =C14*T14 -> 44252.281 | D15: =D14*U14 -> 68.592829 | E15: =C15+D15 -> 44320.874 | G15: =C15*'semicondutcor&electronic'!$D$16*'semicondutcor&electronic'!$E$16 -> 4412.2915 | H15: =D15*'semicondutcor&electronic'!$E$16 -> 32.567764 | I15: =G15+H15 -> 4444.8592 | K15: =G15/'PFAS toxicity'!$L$4*'PFAS toxicity'!$H$3 -> 44185947 | L15: =H15/'PFAS toxicity'!$L$4*'PFAS toxicity'!$H$3 -> 326142.9 | M15: =K15+L15 -> 44512090 | O15: =G15/'PFAS toxicity'!$L$4*'PFAS toxicity'!$I$3 -> 33331710 | P15: =H15/'PFAS toxicity'!$L$4*'PFAS toxicity'!$I$3 -> 246026.2 | Q15: =O15+P15 -> 33577737 | S15: 2028 | T15: =1+'semicondutcor&electronic'!$A$27 -> 1.066 | U15: =1+'semicondutcor&electronic'!$A$29 -> 1.1195 | X15: 2028 | Y15: =Y14*AP14 -> 44252.281 | Z15: =Z14*AQ14 -> 68.592829 | AA15: =Y15+Z15 -> 44320.874 | AC15: =Y15*'semicondutcor&electronic'!$D$16*'semicondutcor&electronic'!$E$17 -> 3750.4477 | AD15: =Z15*'semicondutcor&electronic'!$E$17 -> 27.6826 | AE15: =AC15+AD15 -> 3778.1303 | AG15: =AC15/'PFAS toxicity'!$L$4*'PFAS toxicity'!$H$3 -> 37558055 | AH15: =AD15/'PFAS toxicity'!$L$4*'PFAS toxicity'!$H$3 -> 277221.46 | AI15: =AG15+AH15 -> 37835277 | AK15: =AC15/'PFAS toxicity'!$L$4*'PFAS toxicity'!$I$3 -> 28331954 | AL15: =AD15/'PFAS toxicity'!$L$4*'PFAS toxicity'!$I$3 -> 209122.27 | AM15: =AK15+AL15 -> 28541076 | AO15: 2028 | AP15: =1+'semicondutcor&electronic'!$A$27 -> 1.066 | AQ15: =1+'semicondutcor&electronic'!$A$29 -> 1.1195 | AT15: 2028 | AU15: =AU14*BL14 -> 44252.281 | AV15: =AV14*BM14 -> 54.874263 | AW15: =AU15+AV15 -> 44307.155 | AY15: =AU15*'semicondutcor&electronic'!$D$16*'semicondutcor&electronic'!$E$16 -> 4412.2915 | AZ15: =AV15*'semicondutcor&electronic'!$E$16 -> 26.054211 | BA15: =AY15+AZ15 -> 4438.3457 | BC15: =AY15/'PFAS toxicity'!$L$4*'PFAS toxicity'!$H$3 -> 44185947 | BD15: =AZ15/'PFAS toxicity'!$L$4*'PFAS toxicity'!$H$3 -> 260914.32 | BE15: =BC15+BD15 -> 44446862 | BG15: =AY15/'PFAS toxicity'!$L$4*'PFAS toxicity'!$I$3 -> 33331710 | BH15: =AZ15/'PFAS toxicity'!$L$4*'PFAS toxicity'!$I$3 -> 196820.96 | BI15: =BG15+BH15 -> 33528531 | BK15: 2028 | BL15: =1+'semicondutcor&electronic'!$A$27 -> 1.066 | BM15: =1+'semicondutcor&electronic'!$A$29 -> 1.1195
B16: 2029 | C16: =C15*T15 -> 47172.932 | D16: =D15*U15 -> 76.789672 | E16: =C16+D16 -> 47249.721 | G16: =C16*'semicondutcor&electronic'!$D$16*'semicondutcor&electronic'!$E$16 -> 4703.5027 | H16: =D16*'semicondutcor&electronic'!$E$16 -> 36.459612 | I16: =G16+H16 -> 4739.9623 | K16: =G16/'PFAS toxicity'!$L$4*'PFAS toxicity'!$H$3 -> 47102220 | L16: =H16/'PFAS toxicity'!$L$4*'PFAS toxicity'!$H$3 -> 365116.97 | M16: =K16+L16 -> 47467337 | O16: =G16/'PFAS toxicity'!$L$4*'PFAS toxicity'!$I$3 -> 35531603 | P16: =H16/'PFAS toxicity'!$L$4*'PFAS toxicity'!$I$3 -> 275426.33 | Q16: =O16+P16 -> 35807030 | S16: 2029 | T16: =1+'semicondutcor&electronic'!$A$27 -> 1.066 | U16: =1+'semicondutcor&electronic'!$A$29 -> 1.1195 | X16: 2029 | Y16: =Y15*AP15 -> 47172.932 | Z16: =Z15*AQ15 -> 76.789672 | AA16: =Y16+Z16 -> 47249.721 | AC16: =Y16*'semicondutcor&electronic'!$D$16*'semicondutcor&electronic'!$E$17 -> 3997.9773 | AD16: =Z16*'semicondutcor&electronic'!$E$17 -> 30.99067 | AE16: =AC16+AD16 -> 4028.968 | AG16: =AC16/'PFAS toxicity'!$L$4*'PFAS toxicity'!$H$3 -> 40036887 | AH16: =AD16/'PFAS toxicity'!$L$4*'PFAS toxicity'!$H$3 -> 310349.43 | AI16: =AG16+AH16 -> 40347236 | AK16: =AC16/'PFAS toxicity'!$L$4*'PFAS toxicity'!$I$3 -> 30201863 | AL16: =AD16/'PFAS toxicity'!$L$4*'PFAS toxicity'!$I$3 -> 234112.38 | AM16: =AK16+AL16 -> 30435975 | AO16: 2029 | AP16: =1+'semicondutcor&electronic'!$A$27 -> 1.066 | AQ16: =1+'semicondutcor&electronic'!$A$29 -> 1.1195 | AT16: 2029 | AU16: =AU15*BL15 -> 47172.932 | AV16: =AV15*BM15 -> 61.431737 | AW16: =AU16+AV16 -> 47234.363 | AY16: =AU16*'semicondutcor&electronic'!$D$16*'semicondutcor&electronic'!$E$16 -> 4703.5027 | AZ16: =AV16*'semicondutcor&electronic'!$E$16 -> 29.16769 | BA16: =AY16+AZ16 -> 4732.6704 | BC16: =AY16/'PFAS toxicity'!$L$4*'PFAS toxicity'!$H$3 -> 47102220 | BD16: =AZ16/'PFAS toxicity'!$L$4*'PFAS toxicity'!$H$3 -> 292093.58 | BE16: =BC16+BD16 -> 47394313 | BG16: =AY16/'PFAS toxicity'!$L$4*'PFAS toxicity'!$I$3 -> 35531603 | BH16: =AZ16/'PFAS toxicity'!$L$4*'PFAS toxicity'!$I$3 -> 220341.06 | BI16: =BG16+BH16 -> 35751944 | BK16: 2029 | BL16: =1+'semicondutcor&electronic'!$A$27 -> 1.066 | BM16: =1+'semicondutcor&electronic'!$A$29 -> 1.1195
B17: 2030 | C17: =C16*T16 -> 50286.345 | D17: =D16*U16 -> 85.966037 | E17: =C17+D17 -> 50372.311 | G17: =C17*'semicondutcor&electronic'!$D$16*'semicondutcor&electronic'!$E$16 -> 5013.9339 | H17: =D17*'semicondutcor&electronic'!$E$16 -> 40.816536 | I17: =G17+H17 -> 5054.7504 | K17: =G17/'PFAS toxicity'!$L$4*'PFAS toxicity'!$H$3 -> 50210966 | L17: =H17/'PFAS toxicity'!$L$4*'PFAS toxicity'!$H$3 -> 408748.45 | M17: =K17+L17 -> 50619715 | O17: =G17/'PFAS toxicity'!$L$4*'PFAS toxicity'!$I$3 -> 37876689 | P17: =H17/'PFAS toxicity'!$L$4*'PFAS toxicity'!$I$3 -> 308339.77 | Q17: =O17+P17 -> 38185029 | S17: 2030 | T17: =1+'semicondutcor&electronic'!$A$27 -> 1.066 | U17: =1+'semicondutcor&electronic'!$A$29 -> 1.1195 | X17: 2030 | Y17: =Y16*AP16 -> 50286.345 | Z17: =Z16*AQ16 -> 85.966037 | AA17: =Y17+Z17 -> 50372.311 | AC17: =Y17*'semicondutcor&electronic'!$D$16*'semicondutcor&electronic'!$E$17 -> 4261.8438 | AD17: =Z17*'semicondutcor&electronic'!$E$17 -> 34.694055 | AE17: =AC17+AD17 -> 4296.5379 | AG17: =AC17/'PFAS toxicity'!$L$4*'PFAS toxicity'!$H$3 -> 42679321 | AH17: =AD17/'PFAS toxicity'!$L$4*'PFAS toxicity'!$H$3 -> 347436.18 | AI17: =AG17+AH17 -> 43026758 | AK17: =AC17/'PFAS toxicity'!$L$4*'PFAS toxicity'!$I$3 -> 32195186 | AL17: =AD17/'PFAS toxicity'!$L$4*'PFAS toxicity'!$I$3 -> 262088.81 | AM17: =AK17+AL17 -> 32457275 | AO17: 2030 | AP17: =1+'semicondutcor&electronic'!$A$27 -> 1.066 | AQ17: =1+'semicondutcor&electronic'!$A$29 -> 1.1195 | AT17: 2030 | AU17: =AU16*BL16 -> 50286.345 | AV17: =AV16*BM16 -> 68.77283 | AW17: =AU17+AV17 -> 50355.118 | AY17: =AU17*'semicondutcor&electronic'!$D$16*'semicondutcor&electronic'!$E$16 -> 5013.9339 | AZ17: =AV17*'semicondutcor&electronic'!$E$16 -> 32.653229 | BA17: =AY17+AZ17 -> 5046.5871 | BC17: =AY17/'PFAS toxicity'!$L$4*'PFAS toxicity'!$H$3 -> 50210966 | BD17: =AZ17/'PFAS toxicity'!$L$4*'PFAS toxicity'!$H$3 -> 326998.76 | BE17: =BC17+BD17 -> 50537965 | BG17: =AY17/'PFAS toxicity'!$L$4*'PFAS toxicity'!$I$3 -> 37876689 | BH17: =AZ17/'PFAS toxicity'!$L$4*'PFAS toxicity'!$I$3 -> 246671.82 | BI17: =BG17+BH17 -> 38123361 | BK17: 2030 | BL17: =1+'semicondutcor&electronic'!$A$27 -> 1.066 | BM17: =1+'semicondutcor&electronic'!$A$29 -> 1.1195
B18: 2031 | C18: =C17*T17 -> 53605.244 | D18: =D17*U17 -> 96.238979 | E18: =C18+D18 -> 53701.483 | G18: =C18*'semicondutcor&electronic'!$D$16*'semicondutcor&electronic'!$E$16 -> 5344.8535 | H18: =D18*'semicondutcor&electronic'!$E$16 -> 45.694112 | I18: =G18+H18 -> 5390.5476 | K18: =G18/'PFAS toxicity'!$L$4*'PFAS toxicity'!$H$3 -> 53524890 | L18: =H18/'PFAS toxicity'!$L$4*'PFAS toxicity'!$H$3 -> 457593.89 | M18: =K18+L18 -> 53982484 | O18: =G18/'PFAS toxicity'!$L$4*'PFAS toxicity'!$I$3 -> 40376551 | P18: =H18/'PFAS toxicity'!$L$4*'PFAS toxicity'!$I$3 -> 345186.38 | Q18: =O18+P18 -> 40721737 | S18: 2031 | T18: =1+'semicondutcor&electronic'!$A$27 -> 1.066 | U18: =1+'semicondutcor&electronic'!$A$29 -> 1.1195 | X18: 2031 | Y18: =Y17*AP17 -> 53605.244 | Z18: =Z17*AQ17 -> 96.238979 | AA18: =Y18+Z18 -> 53701.483 | AC18: =Y18*'semicondutcor&electronic'!$D$16*'semicondutcor&electronic'!$E$17 -> 4543.1255 | AD18: =Z18*'semicondutcor&electronic'!$E$17 -> 38.839995 | AE18: =AC18+AD18 -> 4581.9655 | AG18: =AC18/'PFAS toxicity'!$L$4*'PFAS toxicity'!$H$3 -> 45496157 | AH18: =AD18/'PFAS toxicity'!$L$4*'PFAS toxicity'!$H$3 -> 388954.81 | AI18: =AG18+AH18 -> 45885111 | AK18: =AC18/'PFAS toxicity'!$L$4*'PFAS toxicity'!$I$3 -> 34320068 | AL18: =AD18/'PFAS toxicity'!$L$4*'PFAS toxicity'!$I$3 -> 293408.42 | AM18: =AK18+AL18 -> 34613476 | AO18: 2031 | AP18: =1+'semicondutcor&electronic'!$A$27 -> 1.066 | AQ18: =1+'semicondutcor&electronic'!$A$29 -> 1.1195 | AT18: 2031 | AU18: =AU17*BL17 -> 53605.244 | AV18: =AV17*BM17 -> 76.991183 | AW18: =AU18+AV18 -> 53682.235 | AY18: =AU18*'semicondutcor&electronic'!$D$16*'semicondutcor&electronic'!$E$16 -> 5344.8535 | AZ18: =AV18*'semicondutcor&electronic'!$E$16 -> 36.555289 | BA18: =AY18+AZ18 -> 5381.4088 | BC18: =AY18/'PFAS toxicity'!$L$4*'PFAS toxicity'!$H$3 -> 53524890 | BD18: =AZ18/'PFAS toxicity'!$L$4*'PFAS toxicity'!$H$3 -> 366075.11 | BE18: =BC18+BD18 -> 53890965 | BG18: =AY18/'PFAS toxicity'!$L$4*'PFAS toxicity'!$I$3 -> 40376551 | BH18: =AZ18/'PFAS toxicity'!$L$4*'PFAS toxicity'!$I$3 -> 276149.1 | BI18: =BG18+BH18 -> 40652700 | BK18: 2031 | BL18: =1+'semicondutcor&electronic'!$A$27 -> 1.066 | BM18: =1+'semicondutcor&electronic'!$A$29 -> 1.1195
B19: 2032 | C19: =C18*T18 -> 57143.19 | D19: =D18*U18 -> 107.73954 | E19: =C19+D19 -> 57250.93 | G19: =C19*'semicondutcor&electronic'!$D$16*'semicondutcor&electronic'!$E$16 -> 5697.6138 | H19: =D19*'semicondutcor&electronic'!$E$16 -> 51.154558 | I19: =G19+H19 -> 5748.7684 | K19: =G19/'PFAS toxicity'!$L$4*'PFAS toxicity'!$H$3 -> 57057533 | L19: =H19/'PFAS toxicity'!$L$4*'PFAS toxicity'!$H$3 -> 512276.36 | M19: =K19+L19 -> 57569809 | O19: =G19/'PFAS toxicity'!$L$4*'PFAS toxicity'!$I$3 -> 43041403 | P19: =H19/'PFAS toxicity'!$L$4*'PFAS toxicity'!$I$3 -> 386436.15 | Q19: =O19+P19 -> 43427839 | S19: 2032 | T19: =1+'semicondutcor&electronic'!$A$27 -> 1.066 | U19: =1+'semicondutcor&electronic'!$A$29 -> 1.1195 | X19: 2032 | Y19: =Y18*AP18 -> 57143.19 | Z19: =Z18*AQ18 -> 107.73954 | AA19: =Y19+Z19 -> 57250.93 | AC19: =Y19*'semicondutcor&electronic'!$D$16*'semicondutcor&electronic'!$E$17 -> 4842.9718 | AD19: =Z19*'semicondutcor&electronic'!$E$17 -> 43.481374 | AE19: =AC19+AD19 -> 4886.4531 | AG19: =AC19/'PFAS toxicity'!$L$4*'PFAS toxicity'!$H$3 -> 48498903 | AH19: =AD19/'PFAS toxicity'!$L$4*'PFAS toxicity'!$H$3 -> 435434.91 | AI19: =AG19+AH19 -> 48934338 | AK19: =AC19/'PFAS toxicity'!$L$4*'PFAS toxicity'!$I$3 -> 36585192 | AL19: =AD19/'PFAS toxicity'!$L$4*'PFAS toxicity'!$I$3 -> 328470.73 | AM19: =AK19+AL19 -> 36913663 | AO19: 2032 | AP19: =1+'semicondutcor&electronic'!$A$27 -> 1.066 | AQ19: =1+'semicondutcor&electronic'!$A$29 -> 1.1195 | AT19: 2032 | AU19: =AU18*BL18 -> 57143.19 | AV19: =AV18*BM18 -> 86.191629 | AW19: =AU19+AV19 -> 57229.382 | AY19: =AU19*'semicondutcor&electronic'!$D$16*'semicondutcor&electronic'!$E$16 -> 5697.6138 | AZ19: =AV19*'semicondutcor&electronic'!$E$16 -> 40.923647 | BA19: =AY19+AZ19 -> 5738.5375 | BC19: =AY19/'PFAS toxicity'!$L$4*'PFAS toxicity'!$H$3 -> 57057533 | BD19: =AZ19/'PFAS toxicity'!$L$4*'PFAS toxicity'!$H$3 -> 409821.09 | BE19: =BC19+BD19 -> 57467354 | BG19: =AY19/'PFAS toxicity'!$L$4*'PFAS toxicity'!$I$3 -> 43041403 | BH19: =AZ19/'PFAS toxicity'!$L$4*'PFAS toxicity'!$I$3 -> 309148.92 | BI19: =BG19+BH19 -> 43350552 | BK19: 2032 | BL19: =1+'semicondutcor&electronic'!$A$27 -> 1.066 | BM19: =1+'semicondutcor&electronic'!$A$29 -> 1.1195
