Workbook

Sheet Labor-transport-energy-dispoal
AK1: 2023
F2: Price of nature gas 2024 | P2: too small? | W2: https://businessanalytiq.com/procurementanalytics/index/activated-carbon-prices/ | AG2: Price of nature gas 2024 | AK2: https://data.worldbank.org/indicator/ny.gnp.pcap.pp.cd?end=2023&name_desc=false&start=1990 | AO2: https://doi.org/10.1016/j.watres.2023.120324
F3: https://www.globalpetrolprices.com/natural_gas_prices/ | H3: Hazardous incineration regional results | J3: Hazardous waste minimum charge per shipment | L3: haz_transport | N3: non-haz_transport | P3: Transportation distance | W3: $/kg | Y3: $/lb | Z3: $/cf | AC3: piece (37 m2) | AG3: https://www.globalpetrolprices.com/natural_gas_prices/ | AK3: Current international $ | AN3: Basic price
B4: Transport (electricity vehicle) | C4: https://doi.org/10.1038/s41586-020-2448-9 | D4: Electricity | E4: https://www.globalpetrolprices.com/electricity_prices/ | F4: Nature Gas | L4: from initial molde of EPA WBS | P4: Using US as the basic | W4: GAC | Y4: GAC | Z4: IXR | AC4: Membrane | AH4: $/kwh | AK4: labor | AL4: energy price | AN4: GAC | AO4: 2.9 | AP4: $/ton
A5: The united states | B5: 0.00456 | C5: $/t/km | D5: 0.152 | E5: $ kwh | F5: =AH5*29.31 -> 1.08447 | H5: =incineration!B1 -> 1300 | J5: 3392.21 | K5: /shipment | L5: 0.28 | M5: ton/mile | N5: 0.21 | O5: ton/mile | P5: 200 | Q5: mile | R5: The united states | S5: 473.2 | U5: https://www.crwi.org/textfiles/wasman.htm#:~:text=situation%20where%20there%20is%20over,fluctuate%20based%20on%20the%20health | V5: The united states | W5: 1.98 | X5: https://www.imarcgroup.com/activated-carbon-pricing-report#:~:text=Category%20Region%20Price%20Activated%20Carbon,Specialty%20Chemical%20Germany%202388%20USD%2FMT | Y5: =W5*0.4535 -> 0.89793 | Z5: =Z16*43*0.4535 -> 214.5055 | AC5: 740-815 | AD5: https://www.filterwater.com/p-741-dow-filmtec-bw30-400-ro-membrane-10500-gpd.aspx | AE5: https://hydrocomponents.us/products/bw30-400-filmtec-dow-dupont-membranes?srsltid=AfmBOoqvizWo5WT4G4pTw5ZQ-opyEmhKE1_MzjVrcmhfX1U9Q8dl1mrN | AG5: The united states | AH5: 0.037 | AJ5: The united states | AK5: 82340 | AL5: 0.96 | AM5: $/liter | AN5: IXR | AO5: 15.7 | AP5: $/ton
A6: China | B6: 0.0038 | C6: $/t/km | D6: 0.087 | E6: $ kwh | F6: =AH6*29.31 -> 1.34826 | H6: =$H$5*(incineration!$C$6*('Labor-transport-energy-dispoal'!AH6/'Labor-transport-energy-dispoal'!$AH$5)+incineration!$C$5*('Labor-transport-energy-dispoal'!D6/'Labor-transport-energy-dispoal'!$D$5)+incineration!$C$3*('Labor-transport-energy-dispoal'!AK6/'Labor-transport-energy-dispoal'!$AK$5)+0.4187) -> 1390.8652 | I6: https://finance.sina.com.cn/roll/2024-09-16/doc-incpifhu3923087.shtml#:~:text=%E2%80%94%E2%80%94%E5%8D%B1%E5%BA%9F%E7%84%9A%E7%83%A7%E5%A4%84%E7%90%86%E4%BB%B7%E6%A0%BC%EF%BC%9A%E7%BA%A63000%E5%85%83%2F%E5%90%A8 | J6: =$J$5/$AK$5*AK6 -> 1003.5734 | L6: =$L$5*(0.5*AK6/$AK$5+0.5*AL6/$AL$5) -> 0.18783518 | N6: =$N$5*(0.5*AK6/$AK$5+0.5*AL6/$AL$5) -> 0.14087638 | P6: =$P$5*S6/$S$5 -> 27.514793 | R6: China | S6: 65.1 | V6: China | W6: 1.61 | X6: https://www.imarcgroup.com/activated-carbon-pricing-report#:~:text=The%20price%20trend%20for%20activated,an%20overall%20optimistic%20market%20sentiment | Y6: =W6*0.4535 -> 0.730135 | Z6: =Z17*43*0.4535 -> 47.19121 | AC6: 582 | AD6: https://nbhautek.en.made-in-china.com/product/HjRQAevTIJkn/China-Filmtec-Membrane-Bw30-400.html | AE6: https://www.shuitianlan.com/common/2826.html#:~:text=BW30%20PRO,00%E5%85%83%2F%E6%94%AF%EF%BC%88%E5%90%AB%E7%A8%8E%E8%BF%90%EF%BC%89%E3%80%82%E8%BF%99%E4%B8%AA%E4%BB%B7%E6%A0%BC%E6%98%AF%E5%9F%BA%E4%BA%8E%E5%A4%9A%E9%87%8D%E5%9B%A0%E7%B4%A0%E8%BF%9B%E8%A1%8C%E7%9A%84%E6%8A%A5%E4%BB%B7%EF%BC%8C%E9%9C%80%E8%A6%81%E6%B3%A8%E6%84%8F%E7%9A%84%E6%98%AF%EF%BC%8C%E5%85%B7%E4%BD%93%E7%9A%84%E4%BB%B7%E6%A0%BC%E5%8F%AF%E8%83%BD%E4%BC%9A%E5%9B%A0%E4%B8%BA%E5%A4%9A%20%E7%A7%8D%E5%9B%A0%E7%B4%A0%E8%80%8C%E6%9C%89%E6%89%80%E6%B5%AE%E5%8A%A8%E3%80%82%E5%85%B6%E4%BB%B7%E6%A0%BC%E5%BD%B1%E5%93%8D%E5%9B%A0%E7%B4%A0%E5%8C%85%E6%8B%AC%E4%BD%86%E4%B8%8D%E9%99%90%E4%BA%8E%E4%B8%8D%E5%90%8C%E7%9A%84%E7%BB%8F%E9%94%80%E5%95%86%E3%80%81%E5%B8%82%E5%9C%BA%E4%BE%9B%E6%B1%82%E5%85%B3%E7%B3%BB%E3%80%81%E8%B4%AD%E4%B9%B0%E6%95%B0%E9%87%8F%E4%BB%A5%E5%8F%8A%E5%8E%82%E5%AE%B6%E8%B0%83%E6%95%B4%E7%AD%89%E3%80%82%E9%82%A3%E4%B9%88%E8%BF%99%E4%BA%9B%E5%9B%A0%E7%B4%A0%E6%98%AF%E5%A6%82%E4%BD%95%E5%BD%B1%E5%93%8D%E5%85%B6%E4%BB%B7%E6%A0%BC%2F%E6%8A%A5%E4%BB%B7%E7%9A%84%E5%91%A2%EF%BC%9F | AG6: China | AH6: 0.046 | AI6: https://www.ceicdata.com/zh-hans/china/price-monitoring-center-ndrc-36-city-monthly-avg-transaction-price-production-material/cn-usage-price-36-city-avg-natural-gas-natural-gas-for-industry | AJ6: China | AK6: 24360 | AL6: 1.004 | AN6: Membrane
A7: Japan | B7: =$B$5*D7/$D$5 -> 0.00585 | C7: $/t/km | D7: 0.195 | E7: $ kwh | F7: =AH7*29.31 -> 2.43273 | H7: =$H$5*(incineration!$C$6*('Labor-transport-energy-dispoal'!AH7/'Labor-transport-energy-dispoal'!$AH$5)+incineration!$C$5*('Labor-transport-energy-dispoal'!D7/'Labor-transport-energy-dispoal'!$D$5)+incineration!$C$3*('Labor-transport-energy-dispoal'!AK7/'Labor-transport-energy-dispoal'!$AK$5)+0.4187) -> 2090.6381 | I7: https://www.dai-tou.com/marketprice/industrial-waste#:~:text=%E6%B1%9A%E6%B3%A5%2025%2C000%E5%86%86%2F%E3%83%88%E3%83%B3%2015%2C000%E5%86%86%2F%E3%83%88%E3%83%B3%2019%2C000%E5%86%86%2F%E3%83%88%E3%83%B3%20%E7%9F%B3,55%2C000%E5%86%86%2F%E3%83%88%E3%83%B3%20%E3%81%B0%E3%81%84%E3%81%98%E3%82%93%2070%2C000%E5%86%86%2F%E3%83%88%E3%83%B3%2016%2C000%E5%86%86%2F%E3%83%88%E3%83%B3%2034%2C000%E5%86%86%2F%E3%83%88%E3%83%B3 | J7: =$J$5/$AK$5*AK7 -> 2176.8809 | L7: =$L$5*(0.5*AK7/$AK$5+0.5*AL7/$AL$5) -> 0.24952962 | N7: =$N$5*(0.5*AK7/$AK$5+0.5*AL7/$AL$5) -> 0.18714721 | P7: =$P$5*S7/$S$5 -> 42.265427 | R7: Japan | S7: 100 | T7: estimate | V7: Japan | W7: 1.88 | X7: https://www.indexbox.io/search/activated-carbon-price-japan/#:~:text=Activated%20Carbon%20Price%20in%20Japan,2023 | Y7: =W7*0.4535 -> 0.85258 | Z7: =Z18*43*0.4535 -> 185.25475 | AC7: 800-1000 | AD7: https://ja.chunkerowaterplant.com/news/difference-between-8040-ro-membrane-and-4040-ro-membrane#:~:text=%E4%BD%8E%E4%BE%A1%E6%A0%BC%E9%99%90%E5%A4%96%E3%82%8D%E9%81%8EUF%E6%B0%B4%E5%87%A6%E7%90%86%E3%82%B7%E3%82%B9%E3%83%86%E3%83%A0%E8%B3%BC%E8%B2%B7%2C8040%20%E3%83%AD%20%E8%86%9C%E3%81%A8%204040%20%E3%83%AD,8040%20ro%E8%86%9C%E3%81%AE%E4%BE%A1%E6%A0%BC%EF%BC%9A%208040%E8%86%9C%E3%81%AF%E9%9D%A2%E7%A9%8D%E3%81%8C%E5%A4%A7%E3%81%8D%E3%81%8F%E3%80%81%E5%87%A6%E7%90%86%E8%83%BD%E5%8A%9B%E3%81%8C%E5%BC%B7%E3%81%84%E3%81%9F%E3%82%81%E3%80%81%E9%80%9A%E5%B8%B8%E3%81%AF%E4%BE%A1%E6%A0%BC%E3%81%8C%E9%AB%98%E3%81%8F%E3%81%AA%E3%82%8A%E3%81%BE%E3%81%99%E3%80%82%E5%B8%82%E5%A0%B4%E3%81%A7%E3%81%AF%E3%80%818040%20ro%E8%86%9C%E3%81%AE%E4%BE%A1%E6%A0%BC%E3%81%AF500%E3%83%89%E3%83%AB%E3%81%8B%E3%82%891500%E3%83%89%E3%83%AB%E3%81%AE%E7%AF%84%E5%9B%B2%E3%81%A7%E3%80%81%E5%85%B7%E4%BD%93%E7%9A%84%E3%81%AA%E4%BE%A1%E6%A0%BC%E3%81%AF%E3%83%96%E3%83%A9%E3%83%B3%E3%83%89%E3%80%81%E3%83%A2%E3%83%87%E3%83%AB%E3%80%81%E6%80%A7%E8%83%BD%E3%81%AB%E3%82%88%E3%81%A3%E3%81%A6%E7%95%B0%E3%81%AA%E3%82%8A%E3%81%BE%E3%81%99%E3%80%82 | AG7: Japan | AH7: 0.083 | AJ7: Japan | AK7: 52840 | AL7: 1.095
A8: South Korea | B8: =$B$5*D8/$D$5 -> 0.00318 | C8: $/t/km | D8: 0.106 | E8: $ kwh | F8: =AH8*29.31 -> 1.78791 | H8: =$H$5*(incineration!$C$6*('Labor-transport-energy-dispoal'!AH8/'Labor-transport-energy-dispoal'!$AH$5)+incineration!$C$5*('Labor-transport-energy-dispoal'!D8/'Labor-transport-energy-dispoal'!$D$5)+incineration!$C$3*('Labor-transport-energy-dispoal'!AK8/'Labor-transport-energy-dispoal'!$AK$5)+0.4187) -> 1679.9126 | I8: estimate, lack data | J8: =$J$5/$AK$5*AK8 -> 2170.2893 | L8: =$L$5*(0.5*AK8/$AK$5+0.5*AL8/$AL$5) -> 0.26573674 | N8: =$N$5*(0.5*AK8/$AK$5+0.5*AL8/$AL$5) -> 0.19930256 | P8: =$P$5*S8/$S$5 -> 42.265427 | R8: South Korea | S8: 100 | T8: estimate | V8: South Korea | W8: 2.31 | X8: https://www.indexbox.io/search/activated-carbon-price-south-korea/#:~:text=Activated%20Carbon%20Price%20in%20South,2023 | Y8: =W8*0.4535 -> 1.047585 | Z8: =Z19*43*0.4535 -> 156.004 | AC8: 950 | AD8: https://water777.co.kr/goods/view?no=235088#:~:text=%2A%205 | AG8: South Korea | AH8: 0.061 | AJ8: South Korea | AK8: 52680 | AL8: 1.208 | AN8: NaCl, powder | AO8: 120 | AP8: $/ton
A9: Germany | B9: 0.0084 | C9: $/t/km | D9: 0.255 | E9: $ kwh | F9: =AH9*29.31 -> 2.6379 | H9: =$H$5*(incineration!$C$6*('Labor-transport-energy-dispoal'!AH9/'Labor-transport-energy-dispoal'!$AH$5)+incineration!$C$5*('Labor-transport-energy-dispoal'!D9/'Labor-transport-energy-dispoal'!$D$5)+incineration!$C$3*('Labor-transport-energy-dispoal'!AK9/'Labor-transport-energy-dispoal'!$AK$5)+0.4187) -> 2245.1706 | I9: need double check, will highly influence the results | J9: =$J$5/$AK$5*AK9 -> 2913.082 | L9: =$L$5*(0.5*AK9/$AK$5+0.5*AL9/$AL$5) -> 0.37718423 | N9: =$N$5*(0.5*AK9/$AK$5+0.5*AL9/$AL$5) -> 0.28288817 | P9: =$P$5*S9/$S$5 -> 76.373626 | R9: Germany | S9: 180.7 | V9: Germany | W9: 2.39 | X9: https://www.imarcgroup.com/activated-carbon-pricing-report#:~:text=Category%20Region%20Price%20Activated%20Carbon,Specialty%20Chemical%20Germany%202388%20USD%2FMT | Y9: =W9*0.4535 -> 1.083865 | Z9: =Z20*43*0.4535 -> 234.006 | AB9: https://lanxess.com/en/media/press-releases/2022/12/lanxess-increases-prices-for-ion-exchange-resins-and-iron-oxide-adsorbers#:~:text=Specialty%20chemicals%20company%20LANXESS%20will,Customers%20will%20be%20informed%20individually | AC9: 900-1200 | AD9: https://www.wasseraufbereitung-shop24.de/de/umkehrosmose-membranelement-dupont-filmtec-BW30-400#:~:text=shop24.de%20%20Die%20FILMTEC%20BW30,DVGW%20Enth%C3%A4rtungsanlage%20mit%20Zubeh%C3%B6r%20Inkl | AG9: Germany | AH9: 0.09 | AJ9: Germany | AK9: 70710 | AL9: 1.762 | AN9: Methanol | AO9: 372 | AP9: $/ton
A10: Vietnam | B10: =$B$5*D10/$D$5 -> 0.00222 | C10: $/t/km | D10: 0.074 | E10: $ kwh | F10: 0.174 | G10: https://www.vietnam.vn/cap-nhat-thong-tin-moi-ve-thi-truong-khi-dot | H10: =$H$5*(incineration!$C$6*('Labor-transport-energy-dispoal'!AH10/'Labor-transport-energy-dispoal'!$AH$5)+incineration!$C$5*('Labor-transport-energy-dispoal'!D10/'Labor-transport-energy-dispoal'!$D$5)+incineration!$C$3*('Labor-transport-energy-dispoal'!AK10/'Labor-transport-energy-dispoal'!$AK$5)+0.4187) -> 825.60893 | I10: estimate, lack data | J10: =$J$5/$AK$5*AK10 -> 584.59388 | L10: =$L$5*(0.5*AK10/$AK$5+0.5*AL10/$AL$5) -> 0.13335596 | N10: =$N$5*(0.5*AK10/$AK$5+0.5*AL10/$AL$5) -> 0.10001697 | P10: =$P$5*S10/$S$5 -> 42.265427 | R10: Vietnam | S10: 100 | T10: estimate | V10: Vietnam | W10: 2.08 | X10: https://www.indexbox.io/search/activated-carbon-price-vietnam/#:~:text=Activated%20Carbon%20Price%20in%20Vietnam,2023 | Y10: =W10*0.4535 -> 0.94328 | Z10: =Z21*43*0.4535 -> 39.001 | AC10: 600 | AD10: https://otb.vn/mang-loc-ro-dopont-filmtec-bw30-pro-400.html#:~:text=Mi%E1%BB%85n%20ph%C3%AD%3A%20%28 | AG10: Vietnam | AH10: 0.0142 | AI10: https://doi.org/10.3390/su16051969 convert from 0.027 $/kwh electricity 效率大概55% | AJ10: Vietnam | AK10: 14190 | AL10: 0.749 | AN10: Water | AO10: 1.49 | AP10: $/ton
A11: India | B11: 0.0032 | C11: $/t/km | D11: 0.122 | E11: $ kwh | F11: =AH11*29.31 -> 1.72929 | H11: =$H$5*(incineration!$C$6*('Labor-transport-energy-dispoal'!AH11/'Labor-transport-energy-dispoal'!$AH$5)+incineration!$C$5*('Labor-transport-energy-dispoal'!D11/'Labor-transport-energy-dispoal'!$D$5)+incineration!$C$3*('Labor-transport-energy-dispoal'!AK11/'Labor-transport-energy-dispoal'!$AK$5)+0.4187) -> 1616.7761 | J11: =$J$5/$AK$5*AK11 -> 412.79991 | L11: =$L$5*(0.5*AK11/$AK$5+0.5*AL11/$AL$5) -> 0.16841168 | N11: =$N$5*(0.5*AK11/$AK$5+0.5*AL11/$AL$5) -> 0.12630876 | P11: =$P$5*S11/$S$5 -> 87.658495 | R11: India | S11: 207.4 | V11: India | W11: 1.71 | X11: https://www.indexbox.io/blog/india-activated-carbon-exports-2023/#:~:text=Export%20Prices%20by%20Country | Y11: =W11*0.4535 -> 0.775485 | Z11: =Z22*43*0.4535 -> 117.003 | AC11: 480 | AD11: https://www.rotraders.com/membranes/ro-membrane/#:~:text=There%20are%2050%2B%20RO%20Membrane,8040%20CPA%205%20LD | AG11: India | AH11: 0.059 | AJ11: India | AK11: 10020 | AL11: 1.038
H13: non-haz treatement
A14: Om | G14: The united states | Z14: $/cf | AA14: Noted | AB14: 43 | AC14: lbs/ft³ density from the file of EPA
G15: China | Z15: IXR | AB15: 0.4535 | AC15: lb to kg
G16: Japan | Z16: 11 | AA16: https://samcotech.com/how-much-does-it-cost-to-buy-maintain-and-dispose-of-ion-exchange-resins/#:~:text=performance%20characteristics,cubic%20foot%20for%20SBA%2FWBA%20resins
G17: South Korea | Z17: 2.42 | AA17: https://www.hangyan.co/charts/3518217798490784787#:~:text=%E5%9B%BD%E5%86%85%E8%A1%8C%E4%B8%9A%E5%BF%AB%E9%80%9F%E5%8F%91%E5%B1%95%EF%BC%8C%E9%AB%98%E7%AB%AF%E4%BA%A7%E5%93%81%E4%BB%8D%E4%BE%9D%E8%B5%96%E8%BF%9B%E5%8F%A3%E3%80%82%E6%88%91%E5%9B%BD%E7%A6%BB%E5%AD%90%E4%BA%A4%E6%8D%A2%E6%A0%91%E8%84%82%E8%BF%9B%E5%87%BA%E5%8F%A3%E5%B8%82%E5%9C%BA%E5%91%88%E7%8E%B0%E5%87%BA%E5%87%BA%E5%8F%A3%E9%87%8F%E8%BF%9C%E9%AB%98%E4%BA%8E%E8%BF%9B%E5%8F%A3%E9%87%8F%EF%BC%8C%E5%87%BA%E5%8F%A3%E4%BB%B7%E6%A0%BC%E5%8D%B4%E8%BF%9C%E4%BD%8E%E4%BA%8E%E8%BF%9B%E5%8F%A3%E4%BB%B7%E6%A0%BC%E7%9A%84%E7%89%B9%E7%82%B9%EF%BC%8C2023%20%E5%B9%B4%E4%B8%AD%E5%9B%BD%E7%A6%BB%E5%AD%90%E4%BA%A4%E6%8D%A2%E6%A0%91%E8%84%82%E5%87%BA%E5%8F%A3%E9%87%8F%2014,2422%20%E7%BE%8E%E5%85%83%2F%E5%90%A8%EF%BC%8C%E8%BF%9B%E5%8F%A3%E5%9D%87%E4%BB%B7%E7%BA%A6%E4%B8%BA%E5%87%BA%E5%8F%A3%E5%9D%87%E4%BB%B7%E7%9A%84%204%20%E5%80%8D%EF%BC%8C%E9%AB%98%E7%AB%AF%E4%BA%A7%E5%93%81%E5%B0%9A%E6%9C%89%E8%BE%83%E5%A4%A7%E7%9A%84%E8%BF%9B%E5%8F%A3%E6%9B%BF%E4%BB%A3%E6%9C%BA%E4%BC%9A%E3%80%82%E8%BF%91%E5%B9%B4%E6%9D%A5%EF%BC%8C%E4%B8%BA%E7%AA%81%E7%A0%B4%E2%80%9C%E5%8D%A1%E8%84%96%E5%AD%90%E2%80%9D%E7%9A%84%E6%8A%80%E6%9C%AF%E9%99%90%E5%88%B6%EF%BC%8C%E5%9B%BD%E5%AE%B6%E5%AF%B9%E6%96%B0%E6%9D%90%E6%96%99%E3%80%81%E9%AB%98%E7%AB%AF%E4%BA%A7%E4%B8%9A%E5%A4%A7%E5%8A%9B%E6%94%AF%E6%8C%81%EF%BC%8C%E6%94%BF%E7%AD%96%E6%8E%A8%E5%8A%A8%E4%B8%8B%E8%A1%8C%E4%B8%9A%E5%8F%91%E5%B1%95%E8%BF%85%E9%80%9F%EF%BC%8C%E5%9B%BD%E4%BA%A7%E6%9D%90%E6%96%99%E6%80%A7%E8%83%BD%E3%80%81%E7%94%9F%E4%BA%A7%E5%B7%A5%E8%89%BA%E4%B9%9F%E4%B8%8D%E6%96%AD%20%E6%8F%90%E9%AB%98%EF%BC%8C%E5%9B%BD%E4%BA%A7%E4%BA%A7%E5%93%81%E7%9A%84%E5%BA%94%E7%94%A8%E9%A2%86%E5%9F%9F%E4%B9%9F%E9%80%90%E6%B8%90%E4%BB%8E%E5%B7%A5%E4%B8%9A%E6%B0%B4%E5%A4%84%E7%90%86%E9%A2%86%E5%9F%9F%E6%8B%93%E5%B1%95%E5%88%B0%E9%A3%9F%E5%93%81%E3%80%81%E6%A0%B8%E5%B7%A5%E4%B8%9A%E3%80%81
G18: Germany | Z18: 9.5 | AA18: https://b2b.baidu.com/land?id=04c99412b1a5b38969b0812f11daa5cc10#:~:text=%E6%97%A5%E6%9C%AC%E4%B8%89%E8%8F%B1%E5%8C%96%E5%B7%A5%20DIAION%20UBA100%20%E5%BC%BA%E7%A2%B1%E9%98%B4%E7%A6%BB%E5%AD%90%E4%BA%A4%E6%8D%A2%E6%A0%91%E8%84%82%20%E9%80%9A%E7%94%A8%E5%9E%8B%E6%B7%B7%E5%BA%8A%E9%98%B4%E6%A0%91%E8%84%82,
A19: capacity | B19: 2 million one day | G19: Vietnam | Z19: 8 | AA19: https://www.samyangcorp.com/en/chemical-business/ion-exchange-resins#:~:text=Lon%20Exchange%20Resin%20,and%20ultrapure%20water%20for
A20: https://www.sustainalytics.com/esg-research/resource/investors-esg-blog/waste-not-want-not-water-use-in-the-semiconductor-industry | G20: India | Z20: 12 | AA20: https://www.hangyan.co/charts/3518217798490784787#:~:text=%E5%9B%BD%E5%86%85%E8%A1%8C%E4%B8%9A%E5%BF%AB%E9%80%9F%E5%8F%91%E5%B1%95%EF%BC%8C%E9%AB%98%E7%AB%AF%E4%BA%A7%E5%93%81%E4%BB%8D%E4%BE%9D%E8%B5%96%E8%BF%9B%E5%8F%A3%E3%80%82%E6%88%91%E5%9B%BD%E7%A6%BB%E5%AD%90%E4%BA%A4%E6%8D%A2%E6%A0%91%E8%84%82%E8%BF%9B%E5%87%BA%E5%8F%A3%E5%B8%82%E5%9C%BA%E5%91%88%E7%8E%B0%E5%87%BA%E5%87%BA%E5%8F%A3%E9%87%8F%E8%BF%9C%E9%AB%98%E4%BA%8E%E8%BF%9B%E5%8F%A3%E9%87%8F%EF%BC%8C%E5%87%BA%E5%8F%A3%E4%BB%B7%E6%A0%BC%E5%8D%B4%E8%BF%9C%E4%BD%8E%E4%BA%8E%E8%BF%9B%E5%8F%A3%E4%BB%B7%E6%A0%BC%E7%9A%84%E7%89%B9%E7%82%B9%EF%BC%8C2023%20%E5%B9%B4%E4%B8%AD%E5%9B%BD%E7%A6%BB%E5%AD%90%E4%BA%A4%E6%8D%A2%E6%A0%91%E8%84%82%E5%87%BA%E5%8F%A3%E9%87%8F%2014,2422%20%E7%BE%8E%E5%85%83%2F%E5%90%A8%EF%BC%8C%E8%BF%9B%E5%8F%A3%E5%9D%87%E4%BB%B7%E7%BA%A6%E4%B8%BA%E5%87%BA%E5%8F%A3%E5%9D%87%E4%BB%B7%E7%9A%84%204%20%E5%80%8D%EF%BC%8C%E9%AB%98%E7%AB%AF%E4%BA%A7%E5%93%81%E5%B0%9A%E6%9C%89%E8%BE%83%E5%A4%A7%E7%9A%84%E8%BF%9B%E5%8F%A3%E6%9B%BF%E4%BB%A3%E6%9C%BA%E4%BC%9A%E3%80%82%E8%BF%91%E5%B9%B4%E6%9D%A5%EF%BC%8C%E4%B8%BA%E7%AA%81%E7%A0%B4%E2%80%9C%E5%8D%A1%E8%84%96%E5%AD%90%E2%80%9D%E7%9A%84%E6%8A%80%E6%9C%AF%E9%99%90%E5%88%B6%EF%BC%8C%E5%9B%BD%E5%AE%B6%E5%AF%B9%E6%96%B0%E6%9D%90%E6%96%99%E3%80%81%E9%AB%98%E7%AB%AF%E4%BA%A7%E4%B8%9A%E5%A4%A7%E5%8A%9B%E6%94%AF%E6%8C%81%EF%BC%8C%E6%94%BF%E7%AD%96%E6%8E%A8%E5%8A%A8%E4%B8%8B%E8%A1%8C%E4%B8%9A%E5%8F%91%E5%B1%95%E8%BF%85%E9%80%9F%EF%BC%8C%E5%9B%BD%E4%BA%A7%E6%9D%90%E6%96%99%E6%80%A7%E8%83%BD%E3%80%81%E7%94%9F%E4%BA%A7%E5%B7%A5%E8%89%BA%E4%B9%9F%E4%B8%8D%E6%96%AD%20%E6%8F%90%E9%AB%98%EF%BC%8C%E5%9B%BD%E4%BA%A7%E4%BA%A7%E5%93%81%E7%9A%84%E5%BA%94%E7%94%A8%E9%A2%86%E5%9F%9F%E4%B9%9F%E9%80%90%E6%B8%90%E4%BB%8E%E5%B7%A5%E4%B8%9A%E6%B0%B4%E5%A4%84%E7%90%86%E9%A2%86%E5%9F%9F%E6%8B%93%E5%B1%95%E5%88%B0%E9%A3%9F%E5%93%81%E3%80%81%E6%A0%B8%E5%B7%A5%E4%B8%9A%E3%80%81
Z21: 2 | AA21: https://www.vietnamtrades.com/vietnam-import-data/ion-exchange-resin.html#:~:text=RESINEX%20K,2kgs
Z22: 6 | AA22: https://www.zauba.com/import-ANION+EXCHANGE+RESIN-hs-code.html#:~:text=Anion%20Exchange%20Resin%20worth%20%243%2C805%2C746,were%20imported%20from%209%20countries
A25: Basci laber cost(US, the basic results of the WBS model) | E25: China | I25: Japan | M25: South Korea | Q25: Germany | U25: Vietnam | Y25: India
A26: Technical Rate (Loaded) | B26: Managerial Rate (Loaded) | C26: Clerical Rate (Loaded) | E26: Technical Rate (Loaded) | F26: Managerial Rate (Loaded) | G26: Clerical Rate (Loaded) | I26: Technical Rate (Loaded) | J26: Managerial Rate (Loaded) | K26: Clerical Rate (Loaded) | M26: Technical Rate (Loaded) | N26: Managerial Rate (Loaded) | O26: Clerical Rate (Loaded) | Q26: Technical Rate (Loaded) | R26: Managerial Rate (Loaded) | S26: Clerical Rate (Loaded) | U26: Technical Rate (Loaded) | V26: Managerial Rate (Loaded) | W26: Clerical Rate (Loaded) | Y26: Technical Rate (Loaded) | Z26: Managerial Rate (Loaded) | AA26: Clerical Rate (Loaded)
A27: 34.161578 | B27: 50.648663 | C27: 32.900615 | E27: =A27/$AK$5*$AK$6 -> 10.106583 | F27: =B27/$AK$5*$AK$6 -> 14.984229 | G27: =C27/$AK$5*$AK$6 -> 9.7335315 | I27: =A27/$AK$5*$AK$7 -> 21.922489 | J27: =B27/$AK$5*$AK$7 -> 32.502737 | K27: =C27/$AK$5*$AK$7 -> 21.113292 | M27: =A27/$AK$5*$AK$8 -> 21.856108 | N27: =B27/$AK$5*$AK$8 -> 32.404318 | O27: =C27/$AK$5*$AK$8 -> 21.049361 | Q27: =A27/$AK$5*$AK$9 -> 29.336473 | R27: =B27/$AK$5*$AK$9 -> 43.494862 | S27: =C27/$AK$5*$AK$9 -> 28.253613 | U27: =A27/$AK$5*$AK$10 -> 5.887209 | V27: =B27/$AK$5*$AK$10 -> 8.728498 | W27: =C27/$AK$5*$AK$10 -> 5.6699019 | Y27: =A27/$AK$5*$AK$11 -> 4.1571412 | Z27: =B27/$AK$5*$AK$11 -> 6.1634637 | AA27: =C27/$AK$5*$AK$11 -> 4.003694
A28: 34.161578 | B28: 50.648663 | C28: 32.900615 | E28: =A28/$AK$5*$AK$6 -> 10.106583 | F28: =B28/$AK$5*$AK$6 -> 14.984229 | G28: =C28/$AK$5*$AK$6 -> 9.7335315 | I28: =A28/$AK$5*$AK$7 -> 21.922489 | J28: =B28/$AK$5*$AK$7 -> 32.502737 | K28: =C28/$AK$5*$AK$7 -> 21.113292 | M28: =A28/$AK$5*$AK$8 -> 21.856108 | N28: =B28/$AK$5*$AK$8 -> 32.404318 | O28: =C28/$AK$5*$AK$8 -> 21.049361 | Q28: =A28/$AK$5*$AK$9 -> 29.336473 | R28: =B28/$AK$5*$AK$9 -> 43.494862 | S28: =C28/$AK$5*$AK$9 -> 28.253613 | U28: =A28/$AK$5*$AK$10 -> 5.887209 | V28: =B28/$AK$5*$AK$10 -> 8.728498 | W28: =C28/$AK$5*$AK$10 -> 5.6699019 | Y28: =A28/$AK$5*$AK$11 -> 4.1571412 | Z28: =B28/$AK$5*$AK$11 -> 6.1634637 | AA28: =C28/$AK$5*$AK$11 -> 4.003694
A29: 34.161578 | B29: 50.648663 | C29: 32.900615 | E29: =A29/$AK$5*$AK$6 -> 10.106583 | F29: =B29/$AK$5*$AK$6 -> 14.984229 | G29: =C29/$AK$5*$AK$6 -> 9.7335315 | I29: =A29/$AK$5*$AK$7 -> 21.922489 | J29: =B29/$AK$5*$AK$7 -> 32.502737 | K29: =C29/$AK$5*$AK$7 -> 21.113292 | M29: =A29/$AK$5*$AK$8 -> 21.856108 | N29: =B29/$AK$5*$AK$8 -> 32.404318 | O29: =C29/$AK$5*$AK$8 -> 21.049361 | Q29: =A29/$AK$5*$AK$9 -> 29.336473 | R29: =B29/$AK$5*$AK$9 -> 43.494862 | S29: =C29/$AK$5*$AK$9 -> 28.253613 | U29: =A29/$AK$5*$AK$10 -> 5.887209 | V29: =B29/$AK$5*$AK$10 -> 8.728498 | W29: =C29/$AK$5*$AK$10 -> 5.6699019 | Y29: =A29/$AK$5*$AK$11 -> 4.1571412 | Z29: =B29/$AK$5*$AK$11 -> 6.1634637 | AA29: =C29/$AK$5*$AK$11 -> 4.003694
A30: 34.161578 | B30: 50.648663 | C30: 32.900615 | E30: =A30/$AK$5*$AK$6 -> 10.106583 | F30: =B30/$AK$5*$AK$6 -> 14.984229 | G30: =C30/$AK$5*$AK$6 -> 9.7335315 | I30: =A30/$AK$5*$AK$7 -> 21.922489 | J30: =B30/$AK$5*$AK$7 -> 32.502737 | K30: =C30/$AK$5*$AK$7 -> 21.113292 | M30: =A30/$AK$5*$AK$8 -> 21.856108 | N30: =B30/$AK$5*$AK$8 -> 32.404318 | O30: =C30/$AK$5*$AK$8 -> 21.049361 | Q30: =A30/$AK$5*$AK$9 -> 29.336473 | R30: =B30/$AK$5*$AK$9 -> 43.494862 | S30: =C30/$AK$5*$AK$9 -> 28.253613 | U30: =A30/$AK$5*$AK$10 -> 5.887209 | V30: =B30/$AK$5*$AK$10 -> 8.728498 | W30: =C30/$AK$5*$AK$10 -> 5.6699019 | Y30: =A30/$AK$5*$AK$11 -> 4.1571412 | Z30: =B30/$AK$5*$AK$11 -> 6.1634637 | AA30: =C30/$AK$5*$AK$11 -> 4.003694
A31: 36.43131 | B31: 57.930722 | C31: 32.900615 | E31: =A31/$AK$5*$AK$6 -> 10.778075 | F31: =B31/$AK$5*$AK$6 -> 17.138601 | G31: =C31/$AK$5*$AK$6 -> 9.7335315 | I31: =A31/$AK$5*$AK$7 -> 23.379043 | J31: =B31/$AK$5*$AK$7 -> 37.175848 | K31: =C31/$AK$5*$AK$7 -> 21.113292 | M31: =A31/$AK$5*$AK$8 -> 23.308251 | N31: =B31/$AK$5*$AK$8 -> 37.063279 | O31: =C31/$AK$5*$AK$8 -> 21.049361 | Q31: =A31/$AK$5*$AK$9 -> 31.28562 | R31: =B31/$AK$5*$AK$9 -> 49.748377 | S31: =C31/$AK$5*$AK$9 -> 28.253613 | U31: =A31/$AK$5*$AK$10 -> 6.2783616 | V31: =B31/$AK$5*$AK$10 -> 9.983446 | W31: =C31/$AK$5*$AK$10 -> 5.6699019 | Y31: =A31/$AK$5*$AK$11 -> 4.4333462 | Z31: =B31/$AK$5*$AK$11 -> 7.0496215 | AA31: =C31/$AK$5*$AK$11 -> 4.003694
A32: 38.459358 | B32: 64.529759 | C32: 42.48393 | E32: =A32/$AK$5*$AK$6 -> 11.378066 | F32: =B32/$AK$5*$AK$6 -> 19.090903 | G32: =C32/$AK$5*$AK$6 -> 12.568722 | I32: =A32/$AK$5*$AK$7 -> 24.680501 | J32: =B32/$AK$5*$AK$7 -> 41.410645 | K32: =C32/$AK$5*$AK$7 -> 27.263188 | M32: =A32/$AK$5*$AK$8 -> 24.605769 | N32: =B32/$AK$5*$AK$8 -> 41.285253 | O32: =C32/$AK$5*$AK$8 -> 27.180635 | Q32: =A32/$AK$5*$AK$9 -> 33.027219 | R32: =B32/$AK$5*$AK$9 -> 55.415342 | S32: =C32/$AK$5*$AK$9 -> 36.483346 | U32: =A32/$AK$5*$AK$10 -> 6.6278637 | V32: =B32/$AK$5*$AK$10 -> 11.120686 | W32: =C32/$AK$5*$AK$10 -> 7.3214352 | Y32: =A32/$AK$5*$AK$11 -> 4.6801405 | Z32: =B32/$AK$5*$AK$11 -> 7.852662 | AA32: =C32/$AK$5*$AK$11 -> 5.1698929
A33: 40.15115 | B33: 75.300481 | C33: 42.48393 | E33: =A33/$AK$5*$AK$6 -> 11.878577 | F33: =B33/$AK$5*$AK$6 -> 22.277383 | G33: =C33/$AK$5*$AK$6 -> 12.568722 | I33: =A33/$AK$5*$AK$7 -> 25.766174 | J33: =B33/$AK$5*$AK$7 -> 48.322534 | K33: =C33/$AK$5*$AK$7 -> 27.263188 | M33: =A33/$AK$5*$AK$8 -> 25.688154 | N33: =B33/$AK$5*$AK$8 -> 48.176213 | O33: =C33/$AK$5*$AK$8 -> 27.180635 | Q33: =A33/$AK$5*$AK$9 -> 34.480056 | R33: =B33/$AK$5*$AK$9 -> 64.664768 | S33: =C33/$AK$5*$AK$9 -> 36.483346 | U33: =A33/$AK$5*$AK$10 -> 6.9194172 | V33: =B33/$AK$5*$AK$10 -> 12.97685 | W33: =C33/$AK$5*$AK$10 -> 7.3214352 | Y33: =A33/$AK$5*$AK$11 -> 4.8860155 | Z33: =B33/$AK$5*$AK$11 -> 9.1633571 | AA33: =C33/$AK$5*$AK$11 -> 5.1698929
A34: 46.928824 | B34: 80.449412 | C34: 42.48393 | E34: =A34/$AK$5*$AK$6 -> 13.883728 | F34: =B34/$AK$5*$AK$6 -> 23.800676 | G34: =C34/$AK$5*$AK$6 -> 12.568722 | I34: =A34/$AK$5*$AK$7 -> 30.115606 | J34: =B34/$AK$5*$AK$7 -> 51.626754 | K34: =C34/$AK$5*$AK$7 -> 27.263188 | M34: =A34/$AK$5*$AK$8 -> 30.024416 | N34: =B34/$AK$5*$AK$8 -> 51.470428 | O34: =C34/$AK$5*$AK$8 -> 27.180635 | Q34: =A34/$AK$5*$AK$9 -> 40.300426 | R34: =B34/$AK$5*$AK$9 -> 69.086445 | S34: =C34/$AK$5*$AK$9 -> 36.483346 | U34: =A34/$AK$5*$AK$10 -> 8.0874424 | V34: =B34/$AK$5*$AK$10 -> 13.864187 | W34: =C34/$AK$5*$AK$10 -> 7.3214352 | Y34: =A34/$AK$5*$AK$11 -> 5.7107944 | Z34: =B34/$AK$5*$AK$11 -> 9.7899333 | AA34: =C34/$AK$5*$AK$11 -> 5.1698929
A41: Searching
A42: energy
A43: gac_cost_cl | B43: ·
F45: Price of nature gas 2024 | U45: https://businessanalytiq.com/procurementanalytics/index/activated-carbon-prices/
F46: https://www.globalpetrolprices.com/natural_gas_prices/ | H46: incineration regional results | J46: Hazardous waste minimum charge per shipment | L46: haz_transport | N46: non-haz_transport | U46: $/kg | W46: $/lb | X46: $/kg
B47: Transport (electricity vehicle) | C47: https://doi.org/10.1038/s41586-020-2448-9 | D47: Electricity | E47: https://www.globalpetrolprices.com/electricity_prices/ | F47: Nature Gas | L47: from initial molde of EPA WBS | U47: GAC | W47: GAC | X47: IXR | AA47: Membrane
A48: The united states | B48: 0.00456 | C48: $/t/km | D48: 0.152 | E48: $ kwh | F48: 1.08447 | H48: 363 | J48: 3392.21 | K48: /shipment | L48: 0.28 | M48: ton/mile | N48: 0.21 | O48: ton/mile | S48: https://www.crwi.org/textfiles/wasman.htm#:~:text=situation%20where%20there%20is%20over,fluctuate%20based%20on%20the%20health | T48: The united states | U48: 1.98 | V48: https://www.imarcgroup.com/activated-carbon-pricing-report#:~:text=Category%20Region%20Price%20Activated%20Carbon,Specialty%20Chemical%20Germany%202388%20USD%2FMT | W48: 0.89793 | X48: 11 | Y48: https://samcotech.com/how-much-does-it-cost-to-buy-maintain-and-dispose-of-ion-exchange-resins/#:~:text=performance%20characteristics,cubic%20foot%20for%20SBA%2FWBA%20resins | AA48: 740-815 | AB48: https://www.filterwater.com/p-741-dow-filmtec-bw30-400-ro-membrane-10500-gpd.aspx
A49: China | B49: 0.0038 | C49: $/t/km | D49: 0.087 | E49: $ kwh | F49: 1.228089 | H49: 416.66667 | I49: https://finance.sina.com.cn/roll/2024-09-16/doc-incpifhu3923087.shtml#:~:text=%E2%80%94%E2%80%94%E5%8D%B1%E5%BA%9F%E7%84%9A%E7%83%A7%E5%A4%84%E7%90%86%E4%BB%B7%E6%A0%BC%EF%BC%9A%E7%BA%A63000%E5%85%83%2F%E5%90%A8 | J49: 2826.8417 | L49: 0.23333333 | N49: 0.175 | T49: China | U49: 1.61 | V49: https://www.imarcgroup.com/activated-carbon-pricing-report#:~:text=The%20price%20trend%20for%20activated,an%20overall%20optimistic%20market%20sentiment | W49: 0.730135 | X49: 2.42 | Y49: https://www.hangyan.co/charts/3518217798490784787 | AA49: 582 | AB49: https://nbhautek.en.made-in-china.com/product/HjRQAevTIJkn/China-Filmtec-Membrane-Bw30-400.html
A50: Japan | B50: 0.00585 | C50: $/t/km | D50: 0.195 | E50: $ kwh | F50: 2.43273 | H50: 335 | I50: https://www.dai-tou.com/marketprice/industrial-waste#:~:text=%E6%B1%9A%E6%B3%A5%2025%2C000%E5%86%86%2F%E3%83%88%E3%83%B3%2015%2C000%E5%86%86%2F%E3%83%88%E3%83%B3%2019%2C000%E5%86%86%2F%E3%83%88%E3%83%B3%20%E7%9F%B3,55%2C000%E5%86%86%2F%E3%83%88%E3%83%B3%20%E3%81%B0%E3%81%84%E3%81%98%E3%82%93%2070%2C000%E5%86%86%2F%E3%83%88%E3%83%B3%2016%2C000%E5%86%86%2F%E3%83%88%E3%83%B3%2034%2C000%E5%86%86%2F%E3%83%88%E3%83%B3 | J50: 4351.8484 | L50: 0.35921053 | N50: 0.26940789 | T50: Japan | U50: 1.88 | V50: https://www.indexbox.io/search/activated-carbon-price-japan/#:~:text=Activated%20Carbon%20Price%20in%20Japan,2023 | W50: 0.85258 | X50: 9.5 | Y50: https://b2b.baidu.com/land?id=04c99412b1a5b38969b0812f11daa5cc10#:~:text=%E6%97%A5%E6%9C%AC%E4%B8%89%E8%8F%B1%E5%8C%96%E5%B7%A5%20DIAION%20UBA100%20%E5%BC%BA%E7%A2%B1%E9%98%B4%E7%A6%BB%E5%AD%90%E4%BA%A4%E6%8D%A2%E6%A0%91%E8%84%82%20%E9%80%9A%E7%94%A8%E5%9E%8B%E6%B7%B7%E5%BA%8A%E9%98%B4%E6%A0%91%E8%84%82 | AA50: 800-1000 | AB50: https://ja.chunkerowaterplant.com/news/difference-between-8040-ro-membrane-and-4040-ro-membrane#:~:text=%E4%BD%8E%E4%BE%A1%E6%A0%BC%E9%99%90%E5%A4%96%E3%82%8D%E9%81%8EUF%E6%B0%B4%E5%87%A6%E7%90%86%E3%82%B7%E3%82%B9%E3%83%86%E3%83%A0%E8%B3%BC%E8%B2%B7%2C8040%20%E3%83%AD%20%E8%86%9C%E3%81%A8%204040%20%E3%83%AD,8040%20ro%E8%86%9C%E3%81%AE%E4%BE%A1%E6%A0%BC%EF%BC%9A%208040%E8%86%9C%E3%81%AF%E9%9D%A2%E7%A9%8D%E3%81%8C%E5%A4%A7%E3%81%8D%E3%81%8F%E3%80%81%E5%87%A6%E7%90%86%E8%83%BD%E5%8A%9B%E3%81%8C%E5%BC%B7%E3%81%84%E3%81%9F%E3%82%81%E3%80%81%E9%80%9A%E5%B8%B8%E3%81%AF%E4%BE%A1%E6%A0%BC%E3%81%8C%E9%AB%98%E3%81%8F%E3%81%AA%E3%82%8A%E3%81%BE%E3%81%99%E3%80%82%E5%B8%82%E5%A0%B4%E3%81%A7%E3%81%AF%E3%80%818040%20ro%E8%86%9C%E3%81%AE%E4%BE%A1%E6%A0%BC%E3%81%AF500%E3%83%89%E3%83%AB%E3%81%8B%E3%82%891500%E3%83%89%E3%83%AB%E3%81%AE%E7%AF%84%E5%9B%B2%E3%81%A7%E3%80%81%E5%85%B7%E4%BD%93%E7%9A%84%E3%81%AA%E4%BE%A1%E6%A0%BC%E3%81%AF%E3%83%96%E3%83%A9%E3%83%B3%E3%83%89%E3%80%81%E3%83%A2%E3%83%87%E3%83%AB%E3%80%81%E6%80%A7%E8%83%BD%E3%81%AB%E3%82%88%E3%81%A3%E3%81%A6%E7%95%B0%E3%81%AA%E3%82%8A%E3%81%BE%E3%81%99%E3%80%82
...

Sheet labor for RO
AK1: 2023
F2: Price of nature gas 2024 | P2: too small? | W2: https://businessanalytiq.com/procurementanalytics/index/activated-carbon-prices/ | AG2: Price of nature gas 2024 | AK2: https://data.worldbank.org/indicator/ny.gnp.pcap.pp.cd?end=2023&name_desc=false&start=1990 | AO2: https://doi.org/10.1016/j.watres.2023.120324
F3: https://www.globalpetrolprices.com/natural_gas_prices/ | J3: dispoal cost- 2.152 | L3: Mmembrane | P3: Transportation distance | W3: $/kg | Y3: $/lb | Z3: $/cf | AG3: https://www.globalpetrolprices.com/natural_gas_prices/ | AK3: Current international $ | AN3: Basic price
B4: Transport (electricity vehicle) | C4: https://doi.org/10.1038/s41586-020-2448-9 | D4: Electricity | E4: https://www.globalpetrolprices.com/electricity_prices/ | F4: Nature Gas | P4: Using US as the basic | W4: GAC | Y4: GAC | Z4: IXR | AC4: Membrane | AH4: $/kwh | AK4: labor | AL4: energy price | AN4: GAC | AO4: 2.9 | AP4: $/ton
A5: The united states | B5: 0.00456 | C5: $/t/km | D5: 0.152 | E5: $ kwh | F5: =AH5*29.31 -> 1.08447 | J5: 437901.48 | L5: =AC5/400 -> 1.94375 | O5: ton/mile | P5: 200 | Q5: mile | R5: The united states | S5: 473.2 | U5: https://www.crwi.org/textfiles/wasman.htm#:~:text=situation%20where%20there%20is%20over,fluctuate%20based%20on%20the%20health | V5: The united states | W5: 1.98 | X5: https://www.imarcgroup.com/activated-carbon-pricing-report#:~:text=Category%20Region%20Price%20Activated%20Carbon,Specialty%20Chemical%20Germany%202388%20USD%2FMT | Y5: =W5*0.4535 -> 0.89793 | Z5: =Z16*43*0.4535 -> 214.5055 | AC5: =(740+815)/2 -> 777.5 | AD5: https://www.filterwater.com/p-741-dow-filmtec-bw30-400-ro-membrane-10500-gpd.aspx | AE5: https://hydrocomponents.us/products/bw30-400-filmtec-dow-dupont-membranes?srsltid=AfmBOoqvizWo5WT4G4pTw5ZQ-opyEmhKE1_MzjVrcmhfX1U9Q8dl1mrN | AG5: The united states | AH5: 0.037 | AJ5: The united states | AK5: 82340 | AL5: 0.96 | AM5: $/liter | AN5: IXR | AO5: 15.7 | AP5: $/ton
A6: China | B6: 0.0038 | C6: $/t/km | D6: 0.087 | E6: $ kwh | F6: =AH6*29.31 -> 1.34826 | J6: 421703.73 | L6: =AC6/400 -> 1.455 | P6: =$P$5*S6/$S$5 -> 27.514793 | R6: China | S6: 65.1 | V6: China | W6: 1.61 | X6: https://www.imarcgroup.com/activated-carbon-pricing-report#:~:text=The%20price%20trend%20for%20activated,an%20overall%20optimistic%20market%20sentiment | Y6: =W6*0.4535 -> 0.730135 | Z6: =Z17*43*0.4535 -> 47.19121 | AA6: 这个数值要再关注下 | AC6: 582 | AD6: https://nbhautek.en.made-in-china.com/product/HjRQAevTIJkn/China-Filmtec-Membrane-Bw30-400.html | AE6: https://www.shuitianlan.com/common/2826.html#:~:text=BW30%20PRO,00%E5%85%83%2F%E6%94%AF%EF%BC%88%E5%90%AB%E7%A8%8E%E8%BF%90%EF%BC%89%E3%80%82%E8%BF%99%E4%B8%AA%E4%BB%B7%E6%A0%BC%E6%98%AF%E5%9F%BA%E4%BA%8E%E5%A4%9A%E9%87%8D%E5%9B%A0%E7%B4%A0%E8%BF%9B%E8%A1%8C%E7%9A%84%E6%8A%A5%E4%BB%B7%EF%BC%8C%E9%9C%80%E8%A6%81%E6%B3%A8%E6%84%8F%E7%9A%84%E6%98%AF%EF%BC%8C%E5%85%B7%E4%BD%93%E7%9A%84%E4%BB%B7%E6%A0%BC%E5%8F%AF%E8%83%BD%E4%BC%9A%E5%9B%A0%E4%B8%BA%E5%A4%9A%20%E7%A7%8D%E5%9B%A0%E7%B4%A0%E8%80%8C%E6%9C%89%E6%89%80%E6%B5%AE%E5%8A%A8%E3%80%82%E5%85%B6%E4%BB%B7%E6%A0%BC%E5%BD%B1%E5%93%8D%E5%9B%A0%E7%B4%A0%E5%8C%85%E6%8B%AC%E4%BD%86%E4%B8%8D%E9%99%90%E4%BA%8E%E4%B8%8D%E5%90%8C%E7%9A%84%E7%BB%8F%E9%94%80%E5%95%86%E3%80%81%E5%B8%82%E5%9C%BA%E4%BE%9B%E6%B1%82%E5%85%B3%E7%B3%BB%E3%80%81%E8%B4%AD%E4%B9%B0%E6%95%B0%E9%87%8F%E4%BB%A5%E5%8F%8A%E5%8E%82%E5%AE%B6%E8%B0%83%E6%95%B4%E7%AD%89%E3%80%82%E9%82%A3%E4%B9%88%E8%BF%99%E4%BA%9B%E5%9B%A0%E7%B4%A0%E6%98%AF%E5%A6%82%E4%BD%95%E5%BD%B1%E5%93%8D%E5%85%B6%E4%BB%B7%E6%A0%BC%2F%E6%8A%A5%E4%BB%B7%E7%9A%84%E5%91%A2%EF%BC%9F | AG6: China | AH6: 0.046 | AI6: https://www.ceicdata.com/zh-hans/china/price-monitoring-center-ndrc-36-city-monthly-avg-transaction-price-production-material/cn-usage-price-36-city-avg-natural-gas-natural-gas-for-industry | AJ6: China | AK6: 24360 | AL6: 1.004 | AN6: Membrane
A7: Japan | B7: =$B$5*D7/$D$5 -> 0.00585 | C7: $/t/km | D7: 0.195 | E7: $ kwh | F7: =AH7*29.31 -> 2.43273 | J7: 579317 | L7: =AC7/400 -> 2.25 | P7: =$P$5*S7/$S$5 -> 42.265427 | R7: Japan | S7: 100 | T7: estimate | V7: Japan | W7: 1.88 | X7: https://www.indexbox.io/search/activated-carbon-price-japan/#:~:text=Activated%20Carbon%20Price%20in%20Japan,2023 | Y7: =W7*0.4535 -> 0.85258 | Z7: =Z18*43*0.4535 -> 185.25475 | AC7: =(800+1000)/2 -> 900 | AD7: https://ja.chunkerowaterplant.com/news/difference-between-8040-ro-membrane-and-4040-ro-membrane#:~:text=%E4%BD%8E%E4%BE%A1%E6%A0%BC%E9%99%90%E5%A4%96%E3%82%8D%E9%81%8EUF%E6%B0%B4%E5%87%A6%E7%90%86%E3%82%B7%E3%82%B9%E3%83%86%E3%83%A0%E8%B3%BC%E8%B2%B7%2C8040%20%E3%83%AD%20%E8%86%9C%E3%81%A8%204040%20%E3%83%AD,8040%20ro%E8%86%9C%E3%81%AE%E4%BE%A1%E6%A0%BC%EF%BC%9A%208040%E8%86%9C%E3%81%AF%E9%9D%A2%E7%A9%8D%E3%81%8C%E5%A4%A7%E3%81%8D%E3%81%8F%E3%80%81%E5%87%A6%E7%90%86%E8%83%BD%E5%8A%9B%E3%81%8C%E5%BC%B7%E3%81%84%E3%81%9F%E3%82%81%E3%80%81%E9%80%9A%E5%B8%B8%E3%81%AF%E4%BE%A1%E6%A0%BC%E3%81%8C%E9%AB%98%E3%81%8F%E3%81%AA%E3%82%8A%E3%81%BE%E3%81%99%E3%80%82%E5%B8%82%E5%A0%B4%E3%81%A7%E3%81%AF%E3%80%818040%20ro%E8%86%9C%E3%81%AE%E4%BE%A1%E6%A0%BC%E3%81%AF500%E3%83%89%E3%83%AB%E3%81%8B%E3%82%891500%E3%83%89%E3%83%AB%E3%81%AE%E7%AF%84%E5%9B%B2%E3%81%A7%E3%80%81%E5%85%B7%E4%BD%93%E7%9A%84%E3%81%AA%E4%BE%A1%E6%A0%BC%E3%81%AF%E3%83%96%E3%83%A9%E3%83%B3%E3%83%89%E3%80%81%E3%83%A2%E3%83%87%E3%83%AB%E3%80%81%E6%80%A7%E8%83%BD%E3%81%AB%E3%82%88%E3%81%A3%E3%81%A6%E7%95%B0%E3%81%AA%E3%82%8A%E3%81%BE%E3%81%99%E3%80%82 | AG7: Japan | AH7: 0.083 | AJ7: Japan | AK7: 52840 | AL7: 1.095
A8: South Korea | B8: =$B$5*D8/$D$5 -> 0.00318 | C8: $/t/km | D8: 0.106 | E8: $ kwh | F8: =AH8*29.31 -> 1.78791 | J8: 537256.04 | L8: =AC8/400 -> 2.375 | P8: =$P$5*S8/$S$5 -> 42.265427 | R8: South Korea | S8: 100 | T8: estimate | V8: South Korea | W8: 2.31 | X8: https://www.indexbox.io/search/activated-carbon-price-south-korea/#:~:text=Activated%20Carbon%20Price%20in%20South,2023 | Y8: =W8*0.4535 -> 1.047585 | Z8: =Z19*43*0.4535 -> 156.004 | AC8: 950 | AD8: https://water777.co.kr/goods/view?no=235088#:~:text=%2A%205 | AG8: South Korea | AH8: 0.061 | AJ8: South Korea | AK8: 52680 | AL8: 1.208 | AN8: NaCl, powder | AO8: 120 | AP8: $/ton
A9: Germany | B9: 0.0084 | C9: $/t/km | D9: 0.255 | E9: $ kwh | F9: =AH9*29.31 -> 2.6379 | J9: 654902.45 | L9: =AC9/400 -> 2.625 | P9: =$P$5*S9/$S$5 -> 76.373626 | R9: Germany | S9: 180.7 | V9: Germany | W9: 2.39 | X9: https://www.imarcgroup.com/activated-carbon-pricing-report#:~:text=Category%20Region%20Price%20Activated%20Carbon,Specialty%20Chemical%20Germany%202388%20USD%2FMT | Y9: =W9*0.4535 -> 1.083865 | Z9: =Z20*43*0.4535 -> 234.006 | AB9: https://lanxess.com/en/media/press-releases/2022/12/lanxess-increases-prices-for-ion-exchange-resins-and-iron-oxide-adsorbers#:~:text=Specialty%20chemicals%20company%20LANXESS%20will,Customers%20will%20be%20informed%20individually | AC9: =(900+1200)/2 -> 1050 | AD9: https://www.wasseraufbereitung-shop24.de/de/umkehrosmose-membranelement-dupont-filmtec-BW30-400#:~:text=shop24.de%20%20Die%20FILMTEC%20BW30,DVGW%20Enth%C3%A4rtungsanlage%20mit%20Zubeh%C3%B6r%20Inkl | AG9: Germany | AH9: 0.09 | AJ9: Germany | AK9: 70710 | AL9: 1.762 | AN9: Methanol | AO9: 372 | AP9: $/ton
A10: Vietnam | B10: =$B$5*D10/$D$5 -> 0.00222 | C10: $/t/km | D10: 0.074 | E10: $ kwh | F10: 0.174 | G10: https://www.vietnam.vn/cap-nhat-thong-tin-moi-ve-thi-truong-khi-dot | J10: 351625.29 | L10: =AC10/400 -> 1.5 | P10: =$P$5*S10/$S$5 -> 42.265427 | R10: Vietnam | S10: 100 | T10: estimate | V10: Vietnam | W10: 2.08 | X10: https://www.indexbox.io/search/activated-carbon-price-vietnam/#:~:text=Activated%20Carbon%20Price%20in%20Vietnam,2023 | Y10: =W10*0.4535 -> 0.94328 | Z10: =Z21*43*0.4535 -> 39.001 | AC10: 600 | AD10: https://otb.vn/mang-loc-ro-dopont-filmtec-bw30-pro-400.html#:~:text=Mi%E1%BB%85n%20ph%C3%AD%3A%20%28 | AG10: Vietnam | AH10: 0.0142 | AI10: https://doi.org/10.3390/su16051969 convert from 0.027 $/kwh electricity 效率大概55% | AJ10: Vietnam | AK10: 14190 | AL10: 0.749 | AN10: Water | AO10: 1.49 | AP10: $/ton
A11: India | B11: 0.0032 | C11: $/t/km | D11: 0.122 | E11: $ kwh | F11: =AH11*29.31 -> 1.72929 | J11: 472535.87 | L11: =AC11/400 -> 1.2 | P11: =$P$5*S11/$S$5 -> 87.658495 | R11: India | S11: 207.4 | V11: India | W11: 1.71 | X11: https://www.indexbox.io/blog/india-activated-carbon-exports-2023/#:~:text=Export%20Prices%20by%20Country | Y11: =W11*0.4535 -> 0.775485 | Z11: =Z22*43*0.4535 -> 117.003 | AC11: 480 | AD11: https://www.rotraders.com/membranes/ro-membrane/#:~:text=There%20are%2050%2B%20RO%20Membrane,8040%20CPA%205%20LD | AG11: India | AH11: 0.059 | AJ11: India | AK11: 10020 | AL11: 1.038
H13: non-haz treatement
A14: Om | G14: The united states | Z14: $/cf | AA14: Noted | AB14: 43 | AC14: lbs/ft³ density from the file of EPA
G15: China | Z15: IXR | AB15: 0.4535 | AC15: lb to kg
G16: Japan | Z16: 11 | AA16: https://samcotech.com/how-much-does-it-cost-to-buy-maintain-and-dispose-of-ion-exchange-resins/#:~:text=performance%20characteristics,cubic%20foot%20for%20SBA%2FWBA%20resins
G17: South Korea | Z17: 2.42 | AA17: https://www.hangyan.co/charts/3518217798490784787#:~:text=%E5%9B%BD%E5%86%85%E8%A1%8C%E4%B8%9A%E5%BF%AB%E9%80%9F%E5%8F%91%E5%B1%95%EF%BC%8C%E9%AB%98%E7%AB%AF%E4%BA%A7%E5%93%81%E4%BB%8D%E4%BE%9D%E8%B5%96%E8%BF%9B%E5%8F%A3%E3%80%82%E6%88%91%E5%9B%BD%E7%A6%BB%E5%AD%90%E4%BA%A4%E6%8D%A2%E6%A0%91%E8%84%82%E8%BF%9B%E5%87%BA%E5%8F%A3%E5%B8%82%E5%9C%BA%E5%91%88%E7%8E%B0%E5%87%BA%E5%87%BA%E5%8F%A3%E9%87%8F%E8%BF%9C%E9%AB%98%E4%BA%8E%E8%BF%9B%E5%8F%A3%E9%87%8F%EF%BC%8C%E5%87%BA%E5%8F%A3%E4%BB%B7%E6%A0%BC%E5%8D%B4%E8%BF%9C%E4%BD%8E%E4%BA%8E%E8%BF%9B%E5%8F%A3%E4%BB%B7%E6%A0%BC%E7%9A%84%E7%89%B9%E7%82%B9%EF%BC%8C2023%20%E5%B9%B4%E4%B8%AD%E5%9B%BD%E7%A6%BB%E5%AD%90%E4%BA%A4%E6%8D%A2%E6%A0%91%E8%84%82%E5%87%BA%E5%8F%A3%E9%87%8F%2014,2422%20%E7%BE%8E%E5%85%83%2F%E5%90%A8%EF%BC%8C%E8%BF%9B%E5%8F%A3%E5%9D%87%E4%BB%B7%E7%BA%A6%E4%B8%BA%E5%87%BA%E5%8F%A3%E5%9D%87%E4%BB%B7%E7%9A%84%204%20%E5%80%8D%EF%BC%8C%E9%AB%98%E7%AB%AF%E4%BA%A7%E5%93%81%E5%B0%9A%E6%9C%89%E8%BE%83%E5%A4%A7%E7%9A%84%E8%BF%9B%E5%8F%A3%E6%9B%BF%E4%BB%A3%E6%9C%BA%E4%BC%9A%E3%80%82%E8%BF%91%E5%B9%B4%E6%9D%A5%EF%BC%8C%E4%B8%BA%E7%AA%81%E7%A0%B4%E2%80%9C%E5%8D%A1%E8%84%96%E5%AD%90%E2%80%9D%E7%9A%84%E6%8A%80%E6%9C%AF%E9%99%90%E5%88%B6%EF%BC%8C%E5%9B%BD%E5%AE%B6%E5%AF%B9%E6%96%B0%E6%9D%90%E6%96%99%E3%80%81%E9%AB%98%E7%AB%AF%E4%BA%A7%E4%B8%9A%E5%A4%A7%E5%8A%9B%E6%94%AF%E6%8C%81%EF%BC%8C%E6%94%BF%E7%AD%96%E6%8E%A8%E5%8A%A8%E4%B8%8B%E8%A1%8C%E4%B8%9A%E5%8F%91%E5%B1%95%E8%BF%85%E9%80%9F%EF%BC%8C%E5%9B%BD%E4%BA%A7%E6%9D%90%E6%96%99%E6%80%A7%E8%83%BD%E3%80%81%E7%94%9F%E4%BA%A7%E5%B7%A5%E8%89%BA%E4%B9%9F%E4%B8%8D%E6%96%AD%20%E6%8F%90%E9%AB%98%EF%BC%8C%E5%9B%BD%E4%BA%A7%E4%BA%A7%E5%93%81%E7%9A%84%E5%BA%94%E7%94%A8%E9%A2%86%E5%9F%9F%E4%B9%9F%E9%80%90%E6%B8%90%E4%BB%8E%E5%B7%A5%E4%B8%9A%E6%B0%B4%E5%A4%84%E7%90%86%E9%A2%86%E5%9F%9F%E6%8B%93%E5%B1%95%E5%88%B0%E9%A3%9F%E5%93%81%E3%80%81%E6%A0%B8%E5%B7%A5%E4%B8%9A%E3%80%81
G18: Germany | Z18: 9.5 | AA18: https://b2b.baidu.com/land?id=04c99412b1a5b38969b0812f11daa5cc10#:~:text=%E6%97%A5%E6%9C%AC%E4%B8%89%E8%8F%B1%E5%8C%96%E5%B7%A5%20DIAION%20UBA100%20%E5%BC%BA%E7%A2%B1%E9%98%B4%E7%A6%BB%E5%AD%90%E4%BA%A4%E6%8D%A2%E6%A0%91%E8%84%82%20%E9%80%9A%E7%94%A8%E5%9E%8B%E6%B7%B7%E5%BA%8A%E9%98%B4%E6%A0%91%E8%84%82,
A19: capacity | B19: 2 million one day | G19: Vietnam | Z19: 8 | AA19: https://www.samyangcorp.com/en/chemical-business/ion-exchange-resins#:~:text=Lon%20Exchange%20Resin%20,and%20ultrapure%20water%20for
A20: https://www.sustainalytics.com/esg-research/resource/investors-esg-blog/waste-not-want-not-water-use-in-the-semiconductor-industry | G20: India | Z20: 12 | AA20: https://www.hangyan.co/charts/3518217798490784787#:~:text=%E5%9B%BD%E5%86%85%E8%A1%8C%E4%B8%9A%E5%BF%AB%E9%80%9F%E5%8F%91%E5%B1%95%EF%BC%8C%E9%AB%98%E7%AB%AF%E4%BA%A7%E5%93%81%E4%BB%8D%E4%BE%9D%E8%B5%96%E8%BF%9B%E5%8F%A3%E3%80%82%E6%88%91%E5%9B%BD%E7%A6%BB%E5%AD%90%E4%BA%A4%E6%8D%A2%E6%A0%91%E8%84%82%E8%BF%9B%E5%87%BA%E5%8F%A3%E5%B8%82%E5%9C%BA%E5%91%88%E7%8E%B0%E5%87%BA%E5%87%BA%E5%8F%A3%E9%87%8F%E8%BF%9C%E9%AB%98%E4%BA%8E%E8%BF%9B%E5%8F%A3%E9%87%8F%EF%BC%8C%E5%87%BA%E5%8F%A3%E4%BB%B7%E6%A0%BC%E5%8D%B4%E8%BF%9C%E4%BD%8E%E4%BA%8E%E8%BF%9B%E5%8F%A3%E4%BB%B7%E6%A0%BC%E7%9A%84%E7%89%B9%E7%82%B9%EF%BC%8C2023%20%E5%B9%B4%E4%B8%AD%E5%9B%BD%E7%A6%BB%E5%AD%90%E4%BA%A4%E6%8D%A2%E6%A0%91%E8%84%82%E5%87%BA%E5%8F%A3%E9%87%8F%2014,2422%20%E7%BE%8E%E5%85%83%2F%E5%90%A8%EF%BC%8C%E8%BF%9B%E5%8F%A3%E5%9D%87%E4%BB%B7%E7%BA%A6%E4%B8%BA%E5%87%BA%E5%8F%A3%E5%9D%87%E4%BB%B7%E7%9A%84%204%20%E5%80%8D%EF%BC%8C%E9%AB%98%E7%AB%AF%E4%BA%A7%E5%93%81%E5%B0%9A%E6%9C%89%E8%BE%83%E5%A4%A7%E7%9A%84%E8%BF%9B%E5%8F%A3%E6%9B%BF%E4%BB%A3%E6%9C%BA%E4%BC%9A%E3%80%82%E8%BF%91%E5%B9%B4%E6%9D%A5%EF%BC%8C%E4%B8%BA%E7%AA%81%E7%A0%B4%E2%80%9C%E5%8D%A1%E8%84%96%E5%AD%90%E2%80%9D%E7%9A%84%E6%8A%80%E6%9C%AF%E9%99%90%E5%88%B6%EF%BC%8C%E5%9B%BD%E5%AE%B6%E5%AF%B9%E6%96%B0%E6%9D%90%E6%96%99%E3%80%81%E9%AB%98%E7%AB%AF%E4%BA%A7%E4%B8%9A%E5%A4%A7%E5%8A%9B%E6%94%AF%E6%8C%81%EF%BC%8C%E6%94%BF%E7%AD%96%E6%8E%A8%E5%8A%A8%E4%B8%8B%E8%A1%8C%E4%B8%9A%E5%8F%91%E5%B1%95%E8%BF%85%E9%80%9F%EF%BC%8C%E5%9B%BD%E4%BA%A7%E6%9D%90%E6%96%99%E6%80%A7%E8%83%BD%E3%80%81%E7%94%9F%E4%BA%A7%E5%B7%A5%E8%89%BA%E4%B9%9F%E4%B8%8D%E6%96%AD%20%E6%8F%90%E9%AB%98%EF%BC%8C%E5%9B%BD%E4%BA%A7%E4%BA%A7%E5%93%81%E7%9A%84%E5%BA%94%E7%94%A8%E9%A2%86%E5%9F%9F%E4%B9%9F%E9%80%90%E6%B8%90%E4%BB%8E%E5%B7%A5%E4%B8%9A%E6%B0%B4%E5%A4%84%E7%90%86%E9%A2%86%E5%9F%9F%E6%8B%93%E5%B1%95%E5%88%B0%E9%A3%9F%E5%93%81%E3%80%81%E6%A0%B8%E5%B7%A5%E4%B8%9A%E3%80%81
Z21: 2 | AA21: https://www.vietnamtrades.com/vietnam-import-data/ion-exchange-resin.html#:~:text=RESINEX%20K,2kgs
Z22: 6 | AA22: https://www.zauba.com/import-ANION+EXCHANGE+RESIN-hs-code.html#:~:text=Anion%20Exchange%20Resin%20worth%20%243%2C805%2C746,were%20imported%20from%209%20countries
A25: Basci laber cost(US, the basic results of the WBS model) | E25: China | I25: Japan | M25: South Korea | Q25: Germany | U25: Vietnam | Y25: India
A26: Technical Rate (Loaded) | B26: Managerial Rate (Loaded) | C26: Clerical Rate (Loaded) | E26: Technical Rate (Loaded) | F26: Managerial Rate (Loaded) | G26: Clerical Rate (Loaded) | I26: Technical Rate (Loaded) | J26: Managerial Rate (Loaded) | K26: Clerical Rate (Loaded) | M26: Technical Rate (Loaded) | N26: Managerial Rate (Loaded) | O26: Clerical Rate (Loaded) | Q26: Technical Rate (Loaded) | R26: Managerial Rate (Loaded) | S26: Clerical Rate (Loaded) | U26: Technical Rate (Loaded) | V26: Managerial Rate (Loaded) | W26: Clerical Rate (Loaded) | Y26: Technical Rate (Loaded) | Z26: Managerial Rate (Loaded) | AA26: Clerical Rate (Loaded)
A27: 34.161578 | B27: 50.648663 | C27: 32.900615 | E27: =A27/$AK$5*$AK$6 -> 10.106583 | F27: =B27/$AK$5*$AK$6 -> 14.984229 | G27: =C27/$AK$5*$AK$6 -> 9.7335315 | I27: =A27/$AK$5*$AK$7 -> 21.922489 | J27: =B27/$AK$5*$AK$7 -> 32.502737 | K27: =C27/$AK$5*$AK$7 -> 21.113292 | M27: =A27/$AK$5*$AK$8 -> 21.856108 | N27: =B27/$AK$5*$AK$8 -> 32.404318 | O27: =C27/$AK$5*$AK$8 -> 21.049361 | Q27: =A27/$AK$5*$AK$9 -> 29.336473 | R27: =B27/$AK$5*$AK$9 -> 43.494862 | S27: =C27/$AK$5*$AK$9 -> 28.253613 | U27: =A27/$AK$5*$AK$10 -> 5.887209 | V27: =B27/$AK$5*$AK$10 -> 8.728498 | W27: =C27/$AK$5*$AK$10 -> 5.6699019 | Y27: =A27/$AK$5*$AK$11 -> 4.1571412 | Z27: =B27/$AK$5*$AK$11 -> 6.1634637 | AA27: =C27/$AK$5*$AK$11 -> 4.003694
A28: 34.161578 | B28: 50.648663 | C28: 32.900615 | E28: =A28/$AK$5*$AK$6 -> 10.106583 | F28: =B28/$AK$5*$AK$6 -> 14.984229 | G28: =C28/$AK$5*$AK$6 -> 9.7335315 | I28: =A28/$AK$5*$AK$7 -> 21.922489 | J28: =B28/$AK$5*$AK$7 -> 32.502737 | K28: =C28/$AK$5*$AK$7 -> 21.113292 | M28: =A28/$AK$5*$AK$8 -> 21.856108 | N28: =B28/$AK$5*$AK$8 -> 32.404318 | O28: =C28/$AK$5*$AK$8 -> 21.049361 | Q28: =A28/$AK$5*$AK$9 -> 29.336473 | R28: =B28/$AK$5*$AK$9 -> 43.494862 | S28: =C28/$AK$5*$AK$9 -> 28.253613 | U28: =A28/$AK$5*$AK$10 -> 5.887209 | V28: =B28/$AK$5*$AK$10 -> 8.728498 | W28: =C28/$AK$5*$AK$10 -> 5.6699019 | Y28: =A28/$AK$5*$AK$11 -> 4.1571412 | Z28: =B28/$AK$5*$AK$11 -> 6.1634637 | AA28: =C28/$AK$5*$AK$11 -> 4.003694
A29: 34.161578 | B29: 50.648663 | C29: 32.900615 | E29: =A29/$AK$5*$AK$6 -> 10.106583 | F29: =B29/$AK$5*$AK$6 -> 14.984229 | G29: =C29/$AK$5*$AK$6 -> 9.7335315 | I29: =A29/$AK$5*$AK$7 -> 21.922489 | J29: =B29/$AK$5*$AK$7 -> 32.502737 | K29: =C29/$AK$5*$AK$7 -> 21.113292 | M29: =A29/$AK$5*$AK$8 -> 21.856108 | N29: =B29/$AK$5*$AK$8 -> 32.404318 | O29: =C29/$AK$5*$AK$8 -> 21.049361 | Q29: =A29/$AK$5*$AK$9 -> 29.336473 | R29: =B29/$AK$5*$AK$9 -> 43.494862 | S29: =C29/$AK$5*$AK$9 -> 28.253613 | U29: =A29/$AK$5*$AK$10 -> 5.887209 | V29: =B29/$AK$5*$AK$10 -> 8.728498 | W29: =C29/$AK$5*$AK$10 -> 5.6699019 | Y29: =A29/$AK$5*$AK$11 -> 4.1571412 | Z29: =B29/$AK$5*$AK$11 -> 6.1634637 | AA29: =C29/$AK$5*$AK$11 -> 4.003694
A30: 34.161578 | B30: 50.648663 | C30: 32.900615 | E30: =A30/$AK$5*$AK$6 -> 10.106583 | F30: =B30/$AK$5*$AK$6 -> 14.984229 | G30: =C30/$AK$5*$AK$6 -> 9.7335315 | I30: =A30/$AK$5*$AK$7 -> 21.922489 | J30: =B30/$AK$5*$AK$7 -> 32.502737 | K30: =C30/$AK$5*$AK$7 -> 21.113292 | M30: =A30/$AK$5*$AK$8 -> 21.856108 | N30: =B30/$AK$5*$AK$8 -> 32.404318 | O30: =C30/$AK$5*$AK$8 -> 21.049361 | Q30: =A30/$AK$5*$AK$9 -> 29.336473 | R30: =B30/$AK$5*$AK$9 -> 43.494862 | S30: =C30/$AK$5*$AK$9 -> 28.253613 | U30: =A30/$AK$5*$AK$10 -> 5.887209 | V30: =B30/$AK$5*$AK$10 -> 8.728498 | W30: =C30/$AK$5*$AK$10 -> 5.6699019 | Y30: =A30/$AK$5*$AK$11 -> 4.1571412 | Z30: =B30/$AK$5*$AK$11 -> 6.1634637 | AA30: =C30/$AK$5*$AK$11 -> 4.003694
A31: 36.43131 | B31: 57.930722 | C31: 32.900615 | E31: =A31/$AK$5*$AK$6 -> 10.778075 | F31: =B31/$AK$5*$AK$6 -> 17.138601 | G31: =C31/$AK$5*$AK$6 -> 9.7335315 | I31: =A31/$AK$5*$AK$7 -> 23.379043 | J31: =B31/$AK$5*$AK$7 -> 37.175848 | K31: =C31/$AK$5*$AK$7 -> 21.113292 | M31: =A31/$AK$5*$AK$8 -> 23.308251 | N31: =B31/$AK$5*$AK$8 -> 37.063279 | O31: =C31/$AK$5*$AK$8 -> 21.049361 | Q31: =A31/$AK$5*$AK$9 -> 31.28562 | R31: =B31/$AK$5*$AK$9 -> 49.748377 | S31: =C31/$AK$5*$AK$9 -> 28.253613 | U31: =A31/$AK$5*$AK$10 -> 6.2783616 | V31: =B31/$AK$5*$AK$10 -> 9.983446 | W31: =C31/$AK$5*$AK$10 -> 5.6699019 | Y31: =A31/$AK$5*$AK$11 -> 4.4333462 | Z31: =B31/$AK$5*$AK$11 -> 7.0496215 | AA31: =C31/$AK$5*$AK$11 -> 4.003694
A32: 38.459358 | B32: 64.529759 | C32: 42.48393 | E32: =A32/$AK$5*$AK$6 -> 11.378066 | F32: =B32/$AK$5*$AK$6 -> 19.090903 | G32: =C32/$AK$5*$AK$6 -> 12.568722 | I32: =A32/$AK$5*$AK$7 -> 24.680501 | J32: =B32/$AK$5*$AK$7 -> 41.410645 | K32: =C32/$AK$5*$AK$7 -> 27.263188 | M32: =A32/$AK$5*$AK$8 -> 24.605769 | N32: =B32/$AK$5*$AK$8 -> 41.285253 | O32: =C32/$AK$5*$AK$8 -> 27.180635 | Q32: =A32/$AK$5*$AK$9 -> 33.027219 | R32: =B32/$AK$5*$AK$9 -> 55.415342 | S32: =C32/$AK$5*$AK$9 -> 36.483346 | U32: =A32/$AK$5*$AK$10 -> 6.6278637 | V32: =B32/$AK$5*$AK$10 -> 11.120686 | W32: =C32/$AK$5*$AK$10 -> 7.3214352 | Y32: =A32/$AK$5*$AK$11 -> 4.6801405 | Z32: =B32/$AK$5*$AK$11 -> 7.852662 | AA32: =C32/$AK$5*$AK$11 -> 5.1698929
A33: 40.15115 | B33: 75.300481 | C33: 42.48393 | E33: =A33/$AK$5*$AK$6 -> 11.878577 | F33: =B33/$AK$5*$AK$6 -> 22.277383 | G33: =C33/$AK$5*$AK$6 -> 12.568722 | I33: =A33/$AK$5*$AK$7 -> 25.766174 | J33: =B33/$AK$5*$AK$7 -> 48.322534 | K33: =C33/$AK$5*$AK$7 -> 27.263188 | M33: =A33/$AK$5*$AK$8 -> 25.688154 | N33: =B33/$AK$5*$AK$8 -> 48.176213 | O33: =C33/$AK$5*$AK$8 -> 27.180635 | Q33: =A33/$AK$5*$AK$9 -> 34.480056 | R33: =B33/$AK$5*$AK$9 -> 64.664768 | S33: =C33/$AK$5*$AK$9 -> 36.483346 | U33: =A33/$AK$5*$AK$10 -> 6.9194172 | V33: =B33/$AK$5*$AK$10 -> 12.97685 | W33: =C33/$AK$5*$AK$10 -> 7.3214352 | Y33: =A33/$AK$5*$AK$11 -> 4.8860155 | Z33: =B33/$AK$5*$AK$11 -> 9.1633571 | AA33: =C33/$AK$5*$AK$11 -> 5.1698929
A34: 46.928824 | B34: 80.449412 | C34: 42.48393 | E34: =A34/$AK$5*$AK$6 -> 13.883728 | F34: =B34/$AK$5*$AK$6 -> 23.800676 | G34: =C34/$AK$5*$AK$6 -> 12.568722 | I34: =A34/$AK$5*$AK$7 -> 30.115606 | J34: =B34/$AK$5*$AK$7 -> 51.626754 | K34: =C34/$AK$5*$AK$7 -> 27.263188 | M34: =A34/$AK$5*$AK$8 -> 30.024416 | N34: =B34/$AK$5*$AK$8 -> 51.470428 | O34: =C34/$AK$5*$AK$8 -> 27.180635 | Q34: =A34/$AK$5*$AK$9 -> 40.300426 | R34: =B34/$AK$5*$AK$9 -> 69.086445 | S34: =C34/$AK$5*$AK$9 -> 36.483346 | U34: =A34/$AK$5*$AK$10 -> 8.0874424 | V34: =B34/$AK$5*$AK$10 -> 13.864187 | W34: =C34/$AK$5*$AK$10 -> 7.3214352 | Y34: =A34/$AK$5*$AK$11 -> 5.7107944 | Z34: =B34/$AK$5*$AK$11 -> 9.7899333 | AA34: =C34/$AK$5*$AK$11 -> 5.1698929
A41: Searching
A42: energy
A43: gac_cost_cl | B43: ·
F45: Price of nature gas 2024 | U45: https://businessanalytiq.com/procurementanalytics/index/activated-carbon-prices/
F46: https://www.globalpetrolprices.com/natural_gas_prices/ | H46: incineration regional results | J46: Hazardous waste minimum charge per shipment | L46: haz_transport | N46: non-haz_transport | U46: $/kg | W46: $/lb | X46: $/kg
B47: Transport (electricity vehicle) | C47: https://doi.org/10.1038/s41586-020-2448-9 | D47: Electricity | E47: https://www.globalpetrolprices.com/electricity_prices/ | F47: Nature Gas | L47: from initial molde of EPA WBS | U47: GAC | W47: GAC | X47: IXR | AA47: Membrane
A48: The united states | B48: 0.00456 | C48: $/t/km | D48: 0.152 | E48: $ kwh | F48: 1.08447 | H48: 363 | I48: 大电脑的收藏 | J48: 3392.21 | K48: /shipment | L48: 0.28 | M48: ton/mile | N48: 0.21 | O48: ton/mile | S48: https://www.crwi.org/textfiles/wasman.htm#:~:text=situation%20where%20there%20is%20over,fluctuate%20based%20on%20the%20health | T48: The united states | U48: 1.98 | V48: https://www.imarcgroup.com/activated-carbon-pricing-report#:~:text=Category%20Region%20Price%20Activated%20Carbon,Specialty%20Chemical%20Germany%202388%20USD%2FMT | W48: 0.89793 | X48: 11 | Y48: https://samcotech.com/how-much-does-it-cost-to-buy-maintain-and-dispose-of-ion-exchange-resins/#:~:text=performance%20characteristics,cubic%20foot%20for%20SBA%2FWBA%20resins | AA48: 740-815 | AB48: https://www.filterwater.com/p-741-dow-filmtec-bw30-400-ro-membrane-10500-gpd.aspx
A49: China | B49: 0.0038 | C49: $/t/km | D49: 0.087 | E49: $ kwh | F49: 1.228089 | H49: 416.66667 | I49: https://finance.sina.com.cn/roll/2024-09-16/doc-incpifhu3923087.shtml#:~:text=%E2%80%94%E2%80%94%E5%8D%B1%E5%BA%9F%E7%84%9A%E7%83%A7%E5%A4%84%E7%90%86%E4%BB%B7%E6%A0%BC%EF%BC%9A%E7%BA%A63000%E5%85%83%2F%E5%90%A8 | J49: 2826.8417 | L49: 0.23333333 | N49: 0.175 | T49: China | U49: 1.61 | V49: https://www.imarcgroup.com/activated-carbon-pricing-report#:~:text=The%20price%20trend%20for%20activated,an%20overall%20optimistic%20market%20sentiment | W49: 0.730135 | X49: 2.42 | Y49: https://www.hangyan.co/charts/3518217798490784787#:~:text=%E5%9B%BD%E5%86%85%E8%A1%8C%E4%B8%9A%E5%BF%AB%E9%80%9F%E5%8F%91%E5%B1%95%EF%BC%8C%E9%AB%98%E7%AB%AF%E4%BA%A7%E5%93%81%E4%BB%8D%E4%BE%9D%E8%B5%96%E8%BF%9B%E5%8F%A3%E3%80%82%E6%88%91%E5%9B%BD%E7%A6%BB%E5%AD%90%E4%BA%A4%E6%8D%A2%E6%A0%91%E8%84%82%E8%BF%9B%E5%87%BA%E5%8F%A3%E5%B8%82%E5%9C%BA%E5%91%88%E7%8E%B0%E5%87%BA%E5%87%BA%E5%8F%A3%E9%87%8F%E8%BF%9C%E9%AB%98%E4%BA%8E%E8%BF%9B%E5%8F%A3%E9%87%8F%EF%BC%8C%E5%87%BA%E5%8F%A3%E4%BB%B7%E6%A0%BC%E5%8D%B4%E8%BF%9C%E4%BD%8E%E4%BA%8E%E8%BF%9B%E5%8F%A3%E4%BB%B7%E6%A0%BC%E7%9A%84%E7%89%B9%E7%82%B9%EF%BC%8C2023%20%E5%B9%B4%E4%B8%AD%E5%9B%BD%E7%A6%BB%E5%AD%90%E4%BA%A4%E6%8D%A2%E6%A0%91%E8%84%82%E5%87%BA%E5%8F%A3%E9%87%8F%2014,2422%20%E7%BE%8E%E5%85%83%2F%E5%90%A8%EF%BC%8C%E8%BF%9B%E5%8F%A3%E5%9D%87%E4%BB%B7%E7%BA%A6%E4%B8%BA%E5%87%BA%E5%8F%A3%E5%9D%87%E4%BB%B7%E7%9A%84%204%20%E5%80%8D%EF%BC%8C%E9%AB%98%E7%AB%AF%E4%BA%A7%E5%93%81%E5%B0%9A%E6%9C%89%E8%BE%83%E5%A4%A7%E7%9A%84%E8%BF%9B%E5%8F%A3%E6%9B%BF%E4%BB%A3%E6%9C%BA%E4%BC%9A%E3%80%82%E8%BF%91%E5%B9%B4%E6%9D%A5%EF%BC%8C%E4%B8%BA%E7%AA%81%E7%A0%B4%E2%80%9C%E5%8D%A1%E8%84%96%E5%AD%90%E2%80%9D%E7%9A%84%E6%8A%80%E6%9C%AF%E9%99%90%E5%88%B6%EF%BC%8C%E5%9B%BD%E5%AE%B6%E5%AF%B9%E6%96%B0%E6%9D%90%E6%96%99%E3%80%81%E9%AB%98%E7%AB%AF%E4%BA%A7%E4%B8%9A%E5%A4%A7%E5%8A%9B%E6%94%AF%E6%8C%81%EF%BC%8C%E6%94%BF%E7%AD%96%E6%8E%A8%E5%8A%A8%E4%B8%8B%E8%A1%8C%E4%B8%9A%E5%8F%91%E5%B1%95%E8%BF%85%E9%80%9F%EF%BC%8C%E5%9B%BD%E4%BA%A7%E6%9D%90%E6%96%99%E6%80%A7%E8%83%BD%E3%80%81%E7%94%9F%E4%BA%A7%E5%B7%A5%E8%89%BA%E4%B9%9F%E4%B8%8D%E6%96%AD%20%E6%8F%90%E9%AB%98%EF%BC%8C%E5%9B%BD%E4%BA%A7%E4%BA%A7%E5%93%81%E7%9A%84%E5%BA%94%E7%94%A8%E9%A2%86%E5%9F%9F%E4%B9%9F%E9%80%90%E6%B8%90%E4%BB%8E%E5%B7%A5%E4%B8%9A%E6%B0%B4%E5%A4%84%E7%90%86%E9%A2%86%E5%9F%9F%E6%8B%93%E5%B1%95%E5%88%B0%E9%A3%9F%E5%93%81%E3%80%81%E6%A0%B8%E5%B7%A5%E4%B8%9A%E3%80%81 | AA49: 582 | AB49: https://nbhautek.en.made-in-china.com/product/HjRQAevTIJkn/China-Filmtec-Membrane-Bw30-400.html
A50: Japan | B50: 0.00585 | C50: $/t/km | D50: 0.195 | E50: $ kwh | F50: 2.43273 | H50: 335 | I50: https://www.dai-tou.com/marketprice/industrial-waste#:~:text=%E6%B1%9A%E6%B3%A5%2025%2C000%E5%86%86%2F%E3%83%88%E3%83%B3%2015%2C000%E5%86%86%2F%E3%83%88%E3%83%B3%2019%2C000%E5%86%86%2F%E3%83%88%E3%83%B3%20%E7%9F%B3,55%2C000%E5%86%86%2F%E3%83%88%E3%83%B3%20%E3%81%B0%E3%81%84%E3%81%98%E3%82%93%2070%2C000%E5%86%86%2F%E3%83%88%E3%83%B3%2016%2C000%E5%86%86%2F%E3%83%88%E3%83%B3%2034%2C000%E5%86%86%2F%E3%83%88%E3%83%B3 | J50: 4351.8484 | L50: 0.35921053 | N50: 0.26940789 | T50: Japan | U50: 1.88 | V50: https://www.indexbox.io/search/activated-carbon-price-japan/#:~:text=Activated%20Carbon%20Price%20in%20Japan,2023 | W50: 0.85258 | X50: 9.5 | Y50: https://b2b.baidu.com/land?id=04c99412b1a5b38969b0812f11daa5cc10#:~:text=%E6%97%A5%E6%9C%AC%E4%B8%89%E8%8F%B1%E5%8C%96%E5%B7%A5%20DIAION%20UBA100%20%E5%BC%BA%E7%A2%B1%E9%98%B4%E7%A6%BB%E5%AD%90%E4%BA%A4%E6%8D%A2%E6%A0%91%E8%84%82%20%E9%80%9A%E7%94%A8%E5%9E%8B%E6%B7%B7%E5%BA%8A%E9%98%B4%E6%A0%91%E8%84%82, | AA50: 800-1000 | AB50: https://ja.chunkerowaterplant.com/news/difference-between-8040-ro-membrane-and-4040-ro-membrane#:~:text=%E4%BD%8E%E4%BE%A1%E6%A0%BC%E9%99%90%E5%A4%96%E3%82%8D%E9%81%8EUF%E6%B0%B4%E5%87%A6%E7%90%86%E3%82%B7%E3%82%B9%E3%83%86%E3%83%A0%E8%B3%BC%E8%B2%B7%2C8040%20%E3%83%AD%20%E8%86%9C%E3%81%A8%204040%20%E3%83%AD,8040%20ro%E8%86%9C%E3%81%AE%E4%BE%A1%E6%A0%BC%EF%BC%9A%208040%E8%86%9C%E3%81%AF%E9%9D%A2%E7%A9%8D%E3%81%8C%E5%A4%A7%E3%81%8D%E3%81%8F%E3%80%81%E5%87%A6%E7%90%86%E8%83%BD%E5%8A%9B%E3%81%8C%E5%BC%B7%E3%81%84%E3%81%9F%E3%82%81%E3%80%81%E9%80%9A%E5%B8%B8%E3%81%AF%E4%BE%A1%E6%A0%BC%E3%81%8C%E9%AB%98%E3%81%8F%E3%81%AA%E3%82%8A%E3%81%BE%E3%81%99%E3%80%82%E5%B8%82%E5%A0%B4%E3%81%A7%E3%81%AF%E3%80%818040%20ro%E8%86%9C%E3%81%AE%E4%BE%A1%E6%A0%BC%E3%81%AF500%E3%83%89%E3%83%AB%E3%81%8B%E3%82%891500%E3%83%89%E3%83%AB%E3%81%AE%E7%AF%84%E5%9B%B2%E3%81%A7%E3%80%81%E5%85%B7%E4%BD%93%E7%9A%84%E3%81%AA%E4%BE%A1%E6%A0%BC%E3%81%AF%E3%83%96%E3%83%A9%E3%83%B3%E3%83%89%E3%80%81%E3%83%A2%E3%83%87%E3%83%AB%E3%80%81%E6%80%A7%E8%83%BD%E3%81%AB%E3%82%88%E3%81%A3%E3%81%A6%E7%95%B0%E3%81%AA%E3%82%8A%E3%81%BE%E3%81%99%E3%80%82
...

Sheet incineration
A1: Final cost | B1: 1300 | C1: $/ton | D1: https://www.pca.state.mn.us/search?search=PFAS+Removal+and+Destruction+Cost+Evaluation+%241%2C300%2Fton&datasource=entity%3Anode&op=Search&honeypot_time=g1SAygVeKIaLJ4SQ1R-IvarVtxzrioJIGgonFzh_yko&url=
A3: Staffing and administration (labor) | B3: 2300000 | C3: =B3/SUM($B$3:$B$10) -> 0.049515608 | D3: =1-C3-C5-C6 -> 0.41872982
A4: Equipment maintenance | B4: 18000000 | C4: =B4/SUM($B$3:$B$10) -> 0.38751346
A5: Electrical use | B5: 1700000 | C5: =B5/SUM($B$3:$B$10) -> 0.036598493
A6: Natural gas use | B6: 23000000 | C6: =B6/SUM($B$3:$B$10) -> 0.49515608
A7: Chemical use | B7: 170000 | C7: =B7/SUM($B$3:$B$10) -> 0.0036598493
A8: Ash disposal | B8: 300000 | C8: =B8/SUM($B$3:$B$10) -> 0.0064585576
A9: Water costs, wastewater treatment, and surcharges | B9: 980000 | C9: =B9/SUM($B$3:$B$10) -> 0.021097955
A10: Other cost | B10: 0 | C10: =B10/SUM($B$3:$B$10) -> 0

Sheet transport

Sheet electricity
